Workbook

Sheet マスタ
A1: 【マスタ】社員一覧・評価制度概要
A2: ■評価期間
A3: Q1 | B3: 11月〜1月 | C3: Q2 | D3: 2月〜4月
A4: Q3 | B4: 5月〜7月 | C4: Q4 | D4: 8月〜10月
A5: 上半期 | B5: Q1＋Q2 | C5: 下半期 | D5: Q3＋Q4
A6: ■全社売上連動重み
A7: 部長 | B7: 50% | C7: 課長 | D7: 40%
A8: 課長代理 | B8: 35% | C8: 主任 | D8: 30%
A9: 一般 | B9: 20%
A10: ■入力方法
A11: 結果(O列) | B11: 実績を入力 | C11: 尺度結果(P列) | D11: ドロップダウン0〜100
A12: 重み×尺度(Q列) | B12: 自動計算 | C12: 合計点 | D12: 自動計算
A15: ■社員一覧（27名）
A16: No. | B16: 氏名 | C16: 部署 | D16: 役職
A17: 1 | B17: 細田 | C17: リーシング | D17: 課長代理
A18: 2 | B18: 本多 | C18: リーシング | D18: 一般
A19: 3 | B19: 西村 | C19: リーシング | D19: 一般
A20: 4 | B20: 村田 | C20: リーシング | D20: 一般
A21: 5 | B21: 吉田 | C21: リーシング | D21: 一般
A22: 6 | B22: LS新人① | C22: リーシング | D22: 新人
A23: 7 | B23: LS新人② | C23: リーシング | D23: 新人
A24: 8 | B24: 奥村 | C24: カスタマー | D24: 課長代理
A25: 9 | B25: CS新人① | C25: カスタマー | D25: 新人
A26: 10 | B26: CS新人② | C26: カスタマー | D26: 新人
A27: 11 | B27: 野方 | C27: 経営企画 | D27: 課長
A28: 12 | B28: KK新人① | C28: 経営企画 | D28: 新人
... A43: 27 | B43: KS新人② | C43: 管理推進 | D43: 新人

Sheet 細田
A1: 【個人評価シート】 リーシング 課長代理 細田
A3: 【Q1】 11月〜1月
A4: 評価項目 | B4: 重み | C4: 基0 | D4: 基10 | E4: 基20 | F4: 基30 | G4: 基40 | H4: 基50 | I4: 基60 | J4: 基70 | K4: 基80 | L4: 基90 | M4: 基100 | N4: 単位 | O4: 結果(入力) | P4: 尺度結果 | Q4: 重み×尺度
A5: 売上目標達成（全社） | B5: 0.35 | C5: 75未満 | D5: 75 | E5: 80 | F5: 85 | G5: 90 | H5: 95 | I5: 100 | J5: 105 | K5: 110 | L5: 115 | M5: 120〜 | N5: % | Q5: =IF(OR(P5="",NOT(ISNUMBER(P5))),"—",B5*P5/100)
A6: 家賃収入売上UP（課） | B6: 0.4 | C6: 12未満 | D6: 12 | E6: 15 | F6: 18 | G6: 21 | H6: 24 | I6: 27 | J6: 30 | K6: 33 | L6: 36 | M6: 39〜 | N6: 件 | Q6: =IF(OR(P6="",NOT(ISNUMBER(P6))),"—",B6*P6/100)
A7: 仲介手数料売上UP（課） | B7: 0.25 | C7: 9未満 | D7: 9 | E7: 12 | F7: 15 | G7: 18 | H7: 21 | I7: 24 | J7: 27 | K7: 30 | L7: 33 | M7: 36〜 | N7: 件 | Q7: =IF(OR(P7="",NOT(ISNUMBER(P7))),"—",B7*P7/100)
A8: 【加点】入居率アップ | B8: 加点 | N8: 件 | Q8: —
A9: 【加点】テナント物件成約 | B9: 加点 | N9: 件 | Q9: —
A13: Q1 合計点 | Q13: =SUMIF(Q5:Q12,"<>—")
A15: 【Q2】 2月〜4月
A16: 評価項目 | B16: 重み | C16: 基0 | D16: 基10 | E16: 基20 | F16: 基30 | G16: 基40 | H16: 基50 | I16: 基60 | J16: 基70 | K16: 基80 | L16: 基90 | M16: 基100 | N16: 単位 | O16: 結果(入力) | P16: 尺度結果 | Q16: 重み×尺度
A17: 売上目標達成（全社） | B17: 0.35 | C17: 75未満 | D17: 75 | E17: 80 | F17: 85 | G17: 90 | H17: 95 | I17: 100 | J17: 105 | K17: 110 | L17: 115 | M17: 120〜 | N17: % | Q17: =IF(OR(P17="",NOT(ISNUMBER(P17))),"—",B17*P17/100)
A18: 家賃収入売上UP（課） | B18: 0.4 | C18: 12未満 | D18: 12 | E18: 15 | F18: 18 | G18: 21 | H18: 24 | I18: 27 | J18: 30 | K18: 33 | L18: 36 | M18: 39〜 | N18: 件 | Q18: =IF(OR(P18="",NOT(ISNUMBER(P18))),"—",B18*P18/100)
A19: 仲介手数料売上UP（課） | B19: 0.25 | C19: 9未満 | D19: 9 | E19: 12 | F19: 15 | G19: 18 | H19: 21 | I19: 24 | J19: 27 | K19: 30 | L19: 33 | M19: 36〜 | N19: 件 | Q19: =IF(OR(P19="",NOT(ISNUMBER(P19))),"—",B19*P19/100)
A20: 【加点】入居率アップ | B20: 加点 | N20: 件 | Q20: —
A21: 【加点】テナント物件成約 | B21: 加点 | N21: 件 | Q21: —
A25: Q2 合計点 | Q25: =SUMIF(Q17:Q24,"<>—")
A27: 【Q3】 5月〜7月
A28: 評価項目 | B28: 重み | C28: 基0 | D28: 基10 | E28: 基20 | F28: 基30 | G28: 基40 | H28: 基50 | I28: 基60 | J28: 基70 | K28: 基80 | L28: 基90 | M28: 基100 | N28: 単位 | O28: 結果(入力) | P28: 尺度結果 | Q28: 重み×尺度
A29: 売上目標達成（全社） | B29: 0.35 | C29: 75未満 | D29: 75 | E29: 80 | F29: 85 | G29: 90 | H29: 95 | I29: 100 | J29: 105 | K29: 110 | L29: 115 | M29: 120〜 | N29: % | Q29: =IF(OR(P29="",NOT(ISNUMBER(P29))),"—",B29*P29/100)
A30: 家賃収入売上UP（課） | B30: 0.4 | C30: 12未満 | D30: 12 | E30: 15 | F30: 18 | G30: 21 | H30: 24 | I30: 27 | J30: 30 | K30: 33 | L30: 36 | M30: 39〜 | N30: 件 | Q30: =IF(OR(P30="",NOT(ISNUMBER(P30))),"—",B30*P30/100)
A31: 仲介手数料売上UP（課） | B31: 0.25 | C31: 9未満 | D31: 9 | E31: 12 | F31: 15 | G31: 18 | H31: 21 | I31: 24 | J31: 27 | K31: 30 | L31: 33 | M31: 36〜 | N31: 件 | Q31: =IF(OR(P31="",NOT(ISNUMBER(P31))),"—",B31*P31/100)
A32: 【加点】入居率アップ | B32: 加点 | N32: 件 | Q32: —
A33: 【加点】テナント物件成約 | B33: 加点 | N33: 件 | Q33: —
A37: Q3 合計点 | Q37: =SUMIF(Q29:Q36,"<>—")
A39: 【Q4】 8月〜10月
A40: 評価項目 | B40: 重み | C40: 基0 | D40: 基10 | E40: 基20 | F40: 基30 | G40: 基40 | H40: 基50 | I40: 基60 | J40: 基70 | K40: 基80 | L40: 基90 | M40: 基100 | N40: 単位 | O40: 結果(入力) | P40: 尺度結果 | Q40: 重み×尺度
A41: 売上目標達成（全社） | B41: 0.35 | C41: 75未満 | D41: 75 | E41: 80 | F41: 85 | G41: 90 | H41: 95 | I41: 100 | J41: 105 | K41: 110 | L41: 115 | M41: 120〜 | N41: % | Q41: =IF(OR(P41="",NOT(ISNUMBER(P41))),"—",B41*P41/100)
A42: 家賃収入売上UP（課） | B42: 0.4 | C42: 12未満 | D42: 12 | E42: 15 | F42: 18 | G42: 21 | H42: 24 | I42: 27 | J42: 30 | K42: 33 | L42: 36 | M42: 39〜 | N42: 件 | Q42: =IF(OR(P42="",NOT(ISNUMBER(P42))),"—",B42*P42/100)
A43: 仲介手数料売上UP（課） | B43: 0.25 | C43: 9未満 | D43: 9 | E43: 12 | F43: 15 | G43: 18 | H43: 21 | I43: 24 | J43: 27 | K43: 30 | L43: 33 | M43: 36〜 | N43: 件 | Q43: =IF(OR(P43="",NOT(ISNUMBER(P43))),"—",B43*P43/100)
A44: 【加点】入居率アップ | B44: 加点 | N44: 件 | Q44: —
A45: 【加点】テナント物件成約 | B45: 加点 | N45: 件 | Q45: —
A49: Q4 合計点 | Q49: =SUMIF(Q41:Q48,"<>—")
A52: 上半期合計（Q1＋Q2） | Q52: =Q13+Q25
A53: 下半期合計（Q3＋Q4） | Q53: =Q37+Q49

Sheet 本多
A1: 【個人評価シート】 リーシング 一般 本多
A3: 【Q1】 11月〜1月
A4: 評価項目 | B4: 重み | C4: 基0 | D4: 基10 | E4: 基20 | F4: 基30 | G4: 基40 | H4: 基50 | I4: 基60 | J4: 基70 | K4: 基80 | L4: 基90 | M4: 基100 | N4: 単位 | O4: 結果(入力) | P4: 尺度結果 | Q4: 重み×尺度
A5: 目標① | B5: 加点 | Q5: —
A6: 目標② | B6: 加点 | Q6: —
A7: 目標③ | B7: 加点 | Q7: —
A8: 【加点】加点項目 | B8: 加点 | Q8: —
A13: Q1 合計点 | Q13: =SUMIF(Q5:Q12,"<>—")
A15: 【Q2】 2月〜4月
A16: 評価項目 | B16: 重み | C16: 基0 | D16: 基10 | E16: 基20 | F16: 基30 | G16: 基40 | H16: 基50 | I16: 基60 | J16: 基70 | K16: 基80 | L16: 基90 | M16: 基100 | N16: 単位 | O16: 結果(入力) | P16: 尺度結果 | Q16: 重み×尺度
A17: 目標① | B17: 加点 | Q17: —
A18: 目標② | B18: 加点 | Q18: —
A19: 目標③ | B19: 加点 | Q19: —
A20: 【加点】加点項目 | B20: 加点 | Q20: —
A25: Q2 合計点 | Q25: =SUMIF(Q17:Q24,"<>—")
A27: 【Q3】 5月〜7月
A28: 評価項目 | B28: 重み | C28: 基0 | D28: 基10 | E28: 基20 | F28: 基30 | G28: 基40 | H28: 基50 | I28: 基60 | J28: 基70 | K28: 基80 | L28: 基90 | M28: 基100 | N28: 単位 | O28: 結果(入力) | P28: 尺度結果 | Q28: 重み×尺度
A29: 目標① | B29: 加点 | Q29: —
A30: 目標② | B30: 加点 | Q30: —
A31: 目標③ | B31: 加点 | Q31: —
A32: 【加点】加点項目 | B32: 加点 | Q32: —
A37: Q3 合計点 | Q37: =SUMIF(Q29:Q36,"<>—")
A39: 【Q4】 8月〜10月
A40: 評価項目 | B40: 重み | C40: 基0 | D40: 基10 | E40: 基20 | F40: 基30 | G40: 基40 | H40: 基50 | I40: 基60 | J40: 基70 | K40: 基80 | L40: 基90 | M40: 基100 | N40: 単位 | O40: 結果(入力) | P40: 尺度結果 | Q40: 重み×尺度
A41: 目標① | B41: 加点 | Q41: —
A42: 目標② | B42: 加点 | Q42: —
A43: 目標③ | B43: 加点 | Q43: —
A44: 【加点】加点項目 | B44: 加点 | Q44: —
A49: Q4 合計点 | Q49: =SUMIF(Q41:Q48,"<>—")
A52: 上半期合計（Q1＋Q2） | Q52: =Q13+Q25
A53: 下半期合計（Q3＋Q4） | Q53: =Q37+Q49

Sheet 西村
A1: 【個人評価シート】 リーシング 一般 西村
A3: 【Q1】 11月〜1月
A4: 評価項目 | B4: 重み | C4: 基0 | D4: 基10 | E4: 基20 | F4: 基30 | G4: 基40 | H4: 基50 | I4: 基60 | J4: 基70 | K4: 基80 | L4: 基90 | M4: 基100 | N4: 単位 | O4: 結果(入力) | P4: 尺度結果 | Q4: 重み×尺度
A5: 目標① | B5: 加点 | Q5: —
A6: 目標② | B6: 加点 | Q6: —
A7: 目標③ | B7: 加点 | Q7: —
A8: 【加点】加点項目 | B8: 加点 | Q8: —
A13: Q1 合計点 | Q13: =SUMIF(Q5:Q12,"<>—")
A15: 【Q2】 2月〜4月
A16: 評価項目 | B16: 重み | C16: 基0 | D16: 基10 | E16: 基20 | F16: 基30 | G16: 基40 | H16: 基50 | I16: 基60 | J16: 基70 | K16: 基80 | L16: 基90 | M16: 基100 | N16: 単位 | O16: 結果(入力) | P16: 尺度結果 | Q16: 重み×尺度
A17: 目標① | B17: 加点 | Q17: —
A18: 目標② | B18: 加点 | Q18: —
A19: 目標③ | B19: 加点 | Q19: —
A20: 【加点】加点項目 | B20: 加点 | Q20: —
A25: Q2 合計点 | Q25: =SUMIF(Q17:Q24,"<>—")
A27: 【Q3】 5月〜7月
A28: 評価項目 | B28: 重み | C28: 基0 | D28: 基10 | E28: 基20 | F28: 基30 | G28: 基40 | H28: 基50 | I28: 基60 | J28: 基70 | K28: 基80 | L28: 基90 | M28: 基100 | N28: 単位 | O28: 結果(入力) | P28: 尺度結果 | Q28: 重み×尺度
A29: 目標① | B29: 加点 | Q29: —
A30: 目標② | B30: 加点 | Q30: —
A31: 目標③ | B31: 加点 | Q31: —
A32: 【加点】加点項目 | B32: 加点 | Q32: —
A37: Q3 合計点 | Q37: =SUMIF(Q29:Q36,"<>—")
A39: 【Q4】 8月〜10月
A40: 評価項目 | B40: 重み | C40: 基0 | D40: 基10 | E40: 基20 | F40: 基30 | G40: 基40 | H40: 基50 | I40: 基60 | J40: 基70 | K40: 基80 | L40: 基90 | M40: 基100 | N40: 単位 | O40: 結果(入力) | P40: 尺度結果 | Q40: 重み×尺度
A41: 目標① | B41: 加点 | Q41: —
A42: 目標② | B42: 加点 | Q42: —
A43: 目標③ | B43: 加点 | Q43: —
A44: 【加点】加点項目 | B44: 加点 | Q44: —
A49: Q4 合計点 | Q49: =SUMIF(Q41:Q48,"<>—")
A52: 上半期合計（Q1＋Q2） | Q52: =Q13+Q25
A53: 下半期合計（Q3＋Q4） | Q53: =Q37+Q49

Sheet 村田
A1: 【個人評価シート】 リーシング 一般 村田
A3: 【Q1】 11月〜1月
A4: 評価項目 | B4: 重み | C4: 基0 | D4: 基10 | E4: 基20 | F4: 基30 | G4: 基40 | H4: 基50 | I4: 基60 | J4: 基70 | K4: 基80 | L4: 基90 | M4: 基100 | N4: 単位 | O4: 結果(入力) | P4: 尺度結果 | Q4: 重み×尺度
A5: 目標① | B5: 加点 | Q5: —
A6: 目標② | B6: 加点 | Q6: —
A7: 目標③ | B7: 加点 | Q7: —
A8: 【加点】加点項目 | B8: 加点 | Q8: —
A13: Q1 合計点 | Q13: =SUMIF(Q5:Q12,"<>—")
A15: 【Q2】 2月〜4月
A16: 評価項目 | B16: 重み | C16: 基0 | D16: 基10 | E16: 基20 | F16: 基30 | G16: 基40 | H16: 基50 | I16: 基60 | J16: 基70 | K16: 基80 | L16: 基90 | M16: 基100 | N16: 単位 | O16: 結果(入力) | P16: 尺度結果 | Q16: 重み×尺度
A17: 目標① | B17: 加点 | Q17: —
A18: 目標② | B18: 加点 | Q18: —
A19: 目標③ | B19: 加点 | Q19: —
A20: 【加点】加点項目 | B20: 加点 | Q20: —
A25: Q2 合計点 | Q25: =SUMIF(Q17:Q24,"<>—")
A27: 【Q3】 5月〜7月
A28: 評価項目 | B28: 重み | C28: 基0 | D28: 基10 | E28: 基20 | F28: 基30 | G28: 基40 | H28: 基50 | I28: 基60 | J28: 基70 | K28: 基80 | L28: 基90 | M28: 基100 | N28: 単位 | O28: 結果(入力) | P28: 尺度結果 | Q28: 重み×尺度
A29: 目標① | B29: 加点 | Q29: —
A30: 目標② | B30: 加点 | Q30: —
A31: 目標③ | B31: 加点 | Q31: —
A32: 【加点】加点項目 | B32: 加点 | Q32: —
A37: Q3 合計点 | Q37: =SUMIF(Q29:Q36,"<>—")
A39: 【Q4】 8月〜10月
A40: 評価項目 | B40: 重み | C40: 基0 | D40: 基10 | E40: 基20 | F40: 基30 | G40: 基40 | H40: 基50 | I40: 基60 | J40: 基70 | K40: 基80 | L40: 基90 | M40: 基100 | N40: 単位 | O40: 結果(入力) | P40: 尺度結果 | Q40: 重み×尺度
A41: 目標① | B41: 加点 | Q41: —
A42: 目標② | B42: 加点 | Q42: —
A43: 目標③ | B43: 加点 | Q43: —
A44: 【加点】加点項目 | B44: 加点 | Q44: —
A49: Q4 合計点 | Q49: =SUMIF(Q41:Q48,"<>—")
A52: 上半期合計（Q1＋Q2） | Q52: =Q13+Q25
A53: 下半期合計（Q3＋Q4） | Q53: =Q37+Q49

Sheet 吉田
A1: 【個人評価シート】 リーシング 一般 吉田
A3: 【Q1】 11月〜1月
A4: 評価項目 | B4: 重み | C4: 基0 | D4: 基10 | E4: 基20 | F4: 基30 | G4: 基40 | H4: 基50 | I4: 基60 | J4: 基70 | K4: 基80 | L4: 基90 | M4: 基100 | N4: 単位 | O4: 結果(入力) | P4: 尺度結果 | Q4: 重み×尺度
A5: 目標① | B5: 加点 | Q5: —
A6: 目標② | B6: 加点 | Q6: —
A7: 目標③ | B7: 加点 | Q7: —
A8: 【加点】加点項目 | B8: 加点 | Q8: —
A13: Q1 合計点 | Q13: =SUMIF(Q5:Q12,"<>—")
A15: 【Q2】 2月〜4月
A16: 評価項目 | B16: 重み | C16: 基0 | D16: 基10 | E16: 基20 | F16: 基30 | G16: 基40 | H16: 基50 | I16: 基60 | J16: 基70 | K16: 基80 | L16: 基90 | M16: 基100 | N16: 単位 | O16: 結果(入力) | P16: 尺度結果 | Q16: 重み×尺度
A17: 目標① | B17: 加点 | Q17: —
A18: 目標② | B18: 加点 | Q18: —
A19: 目標③ | B19: 加点 | Q19: —
A20: 【加点】加点項目 | B20: 加点 | Q20: —
A25: Q2 合計点 | Q25: =SUMIF(Q17:Q24,"<>—")
A27: 【Q3】 5月〜7月
A28: 評価項目 | B28: 重み | C28: 基0 | D28: 基10 | E28: 基20 | F28: 基30 | G28: 基40 | H28: 基50 | I28: 基60 | J28: 基70 | K28: 基80 | L28: 基90 | M28: 基100 | N28: 単位 | O28: 結果(入力) | P28: 尺度結果 | Q28: 重み×尺度
A29: 目標① | B29: 加点 | Q29: —
A30: 目標② | B30: 加点 | Q30: —
A31: 目標③ | B31: 加点 | Q31: —
A32: 【加点】加点項目 | B32: 加点 | Q32: —
A37: Q3 合計点 | Q37: =SUMIF(Q29:Q36,"<>—")
A39: 【Q4】 8月〜10月
A40: 評価項目 | B40: 重み | C40: 基0 | D40: 基10 | E40: 基20 | F40: 基30 | G40: 基40 | H40: 基50 | I40: 基60 | J40: 基70 | K40: 基80 | L40: 基90 | M40: 基100 | N40: 単位 | O40: 結果(入力) | P40: 尺度結果 | Q40: 重み×尺度
A41: 目標① | B41: 加点 | Q41: —
A42: 目標② | B42: 加点 | Q42: —
A43: 目標③ | B43: 加点 | Q43: —
A44: 【加点】加点項目 | B44: 加点 | Q44: —
A49: Q4 合計点 | Q49: =SUMIF(Q41:Q48,"<>—")
A52: 上半期合計（Q1＋Q2） | Q52: =Q13+Q25
A53: 下半期合計（Q3＋Q4） | Q53: =Q37+Q49

Sheet LS新人①
A1: 【個人評価シート】 リーシング 新人 LS新人①
A3: 【Q1】 11月〜1月
A4: 評価項目 | B4: 重み | C4: 基0 | D4: 基10 | E4: 基20 | F4: 基30 | G4: 基40 | H4: 基50 | I4: 基60 | J4: 基70 | K4: 基80 | L4: 基90 | M4: 基100 | N4: 単位 | O4: 結果(入力) | P4: 尺度結果 | Q4: 重み×尺度
A5: 目標① | B5: 加点 | Q5: —
A6: 目標② | B6: 加点 | Q6: —
A7: 目標③ | B7: 加点 | Q7: —
A8: 【加点】加点項目 | B8: 加点 | Q8: —
A13: Q1 合計点 | Q13: =SUMIF(Q5:Q12,"<>—")
A15: 【Q2】 2月〜4月
A16: 評価項目 | B16: 重み | C16: 基0 | D16: 基10 | E16: 基20 | F16: 基30 | G16: 基40 | H16: 基50 | I16: 基60 | J16: 基70 | K16: 基80 | L16: 基90 | M16: 基100 | N16: 単位 | O16: 結果(入力) | P16: 尺度結果 | Q16: 重み×尺度
A17: 目標① | B17: 加点 | Q17: —
A18: 目標② | B18: 加点 | Q18: —
A19: 目標③ | B19: 加点 | Q19: —
A20: 【加点】加点項目 | B20: 加点 | Q20: —
A25: Q2 合計点 | Q25: =SUMIF(Q17:Q24,"<>—")
A27: 【Q3】 5月〜7月
A28: 評価項目 | B28: 重み | C28: 基0 | D28: 基10 | E28: 基20 | F28: 基30 | G28: 基40 | H28: 基50 | I28: 基60 | J28: 基70 | K28: 基80 | L28: 基90 | M28: 基100 | N28: 単位 | O28: 結果(入力) | P28: 尺度結果 | Q28: 重み×尺度
A29: 目標① | B29: 加点 | Q29: —
A30: 目標② | B30: 加点 | Q30: —
A31: 目標③ | B31: 加点 | Q31: —
A32: 【加点】加点項目 | B32: 加点 | Q32: —
A37: Q3 合計点 | Q37: =SUMIF(Q29:Q36,"<>—")
A39: 【Q4】 8月〜10月
A40: 評価項目 | B40: 重み | C40: 基0 | D40: 基10 | E40: 基20 | F40: 基30 | G40: 基40 | H40: 基50 | I40: 基60 | J40: 基70 | K40: 基80 | L40: 基90 | M40: 基100 | N40: 単位 | O40: 結果(入力) | P40: 尺度結果 | Q40: 重み×尺度
A41: 目標① | B41: 加点 | Q41: —
A42: 目標② | B42: 加点 | Q42: —
A43: 目標③ | B43: 加点 | Q43: —
A44: 【加点】加点項目 | B44: 加点 | Q44: —
A49: Q4 合計点 | Q49: =SUMIF(Q41:Q48,"<>—")
A52: 上半期合計（Q1＋Q2） | Q52: =Q13+Q25
A53: 下半期合計（Q3＋Q4） | Q53: =Q37+Q49

Sheet LS新人②
A1: 【個人評価シート】 リーシング 新人 LS新人②
A3: 【Q1】 11月〜1月
A4: 評価項目 | B4: 重み | C4: 基0 | D4: 基10 | E4: 基20 | F4: 基30 | G4: 基40 | H4: 基50 | I4: 基60 | J4: 基70 | K4: 基80 | L4: 基90 | M4: 基100 | N4: 単位 | O4: 結果(入力) | P4: 尺度結果 | Q4: 重み×尺度
A5: 目標① | B5: 加点 | Q5: —
A6: 目標② | B6: 加点 | Q6: —
A7: 目標③ | B7: 加点 | Q7: —
A8: 【加点】加点項目 | B8: 加点 | Q8: —
A13: Q1 合計点 | Q13: =SUMIF(Q5:Q12,"<>—")
A15: 【Q2】 2月〜4月
A16: 評価項目 | B16: 重み | C16: 基0 | D16: 基10 | E16: 基20 | F16: 基30 | G16: 基40 | H16: 基50 | I16: 基60 | J16: 基70 | K16: 基80 | L16: 基90 | M16: 基100 | N16: 単位 | O16: 結果(入力) | P16: 尺度結果 | Q16: 重み×尺度
A17: 目標① | B17: 加点 | Q17: —
A18: 目標② | B18: 加点 | Q18: —
A19: 目標③ | B19: 加点 | Q19: —
A20: 【加点】加点項目 | B20: 加点 | Q20: —
A25: Q2 合計点 | Q25: =SUMIF(Q17:Q24,"<>—")
A27: 【Q3】 5月〜7月
A28: 評価項目 | B28: 重み | C28: 基0 | D28: 基10 | E28: 基20 | F28: 基30 | G28: 基40 | H28: 基50 | I28: 基60 | J28: 基70 | K28: 基80 | L28: 基90 | M28: 基100 | N28: 単位 | O28: 結果(入力) | P28: 尺度結果 | Q28: 重み×尺度
A29: 目標① | B29: 加点 | Q29: —
A30: 目標② | B30: 加点 | Q30: —
A31: 目標③ | B31: 加点 | Q31: —
A32: 【加点】加点項目 | B32: 加点 | Q32: —
A37: Q3 合計点 | Q37: =SUMIF(Q29:Q36,"<>—")
A39: 【Q4】 8月〜10月
A40: 評価項目 | B40: 重み | C40: 基0 | D40: 基10 | E40: 基20 | F40: 基30 | G40: 基40 | H40: 基50 | I40: 基60 | J40: 基70 | K40: 基80 | L40: 基90 | M40: 基100 | N40: 単位 | O40: 結果(入力) | P40: 尺度結果 | Q40: 重み×尺度
A41: 目標① | B41: 加点 | Q41: —
A42: 目標② | B42: 加点 | Q42: —
A43: 目標③ | B43: 加点 | Q43: —
A44: 【加点】加点項目 | B44: 加点 | Q44: —
A49: Q4 合計点 | Q49: =SUMIF(Q41:Q48,"<>—")
A52: 上半期合計（Q1＋Q2） | Q52: =Q13+Q25
A53: 下半期合計（Q3＋Q4） | Q53: =Q37+Q49

Sheet 奥村
A1: 【個人評価シート】 カスタマー 課長代理 奥村
A3: 【Q1】 11月〜1月
A4: 評価項目 | B4: 重み | C4: 基0 | D4: 基10 | E4: 基20 | F4: 基30 | G4: 基40 | H4: 基50 | I4: 基60 | J4: 基70 | K4: 基80 | L4: 基90 | M4: 基100 | N4: 単位 | O4: 結果(入力) | P4: 尺度結果 | Q4: 重み×尺度
A5: 売上目標達成（全社） | B5: 0.35 | C5: 75未満 | D5: 75 | E5: 80 | F5: 85 | G5: 90 | H5: 95 | I5: 100 | J5: 105 | K5: 110 | L5: 115 | M5: 120〜 | N5: % | Q5: =IF(OR(P5="",NOT(ISNUMBER(P5))),"—",B5*P5/100)
A6: お困りごと残件数削減（課） | B6: 0.25 | C6: 91〜 | D6: 90 | E6: 82 | F6: 74 | G6: 66 | H6: 58 | I6: 50 | J6: 42 | K6: 34 | L6: 26 | M6: 〜18 | N6: 件 | Q6: =IF(OR(P6="",NOT(ISNUMBER(P6))),"—",B6*P6/100)
A7: 顧客満足度向上（課） | B7: 0.1 | C7: 4.75未満 | D7: — | E7: 4.75 | F7: — | G7: 4.8 | H7: — | I7: 4.85 | J7: +口コミ15 | K7: 20 | L7: 25 | M7: 30 | N7: 点/件 | Q7: =IF(OR(P7="",NOT(ISNUMBER(P7))),"—",B7*P7/100)
A8: アンケート回収率UP（課） | B8: 0.1 | C8: 10未満 | D8: — | E8: 10 | F8: 15 | G8: 20 | H8: 25 | I8: 30 | J8: 35 | K8: 40 | L8: 45 | M8: 50〜 | N8: % | Q8: =IF(OR(P8="",NOT(ISNUMBER(P8))),"—",B8*P8/100)
A9: 原状回復の対応（課） | B9: 0.2 | C9: 7〜 | D9: 6 | E9: 5 | F9: 4 | G9: 3 | H9: 2 | I9: 1 | J9: 60点+3件 | K9: +5件 | L9: +7件 | M9: +9件 | N9: 件 | Q9: =IF(OR(P9="",NOT(ISNUMBER(P9))),"—",B9*P9/100)
A13: Q1 合計点 | Q13: =SUMIF(Q5:Q12,"<>—")
A15: 【Q2】 2月〜4月
A16: 評価項目 | B16: 重み | C16: 基0 | D16: 基10 | E16: 基20 | F16: 基30 | G16: 基40 | H16: 基50 | I16: 基60 | J16: 基70 | K16: 基80 | L16: 基90 | M16: 基100 | N16: 単位 | O16: 結果(入力) | P16: 尺度結果 | Q16: 重み×尺度
A17: 売上目標達成（全社） | B17: 0.35 | C17: 75未満 | D17: 75 | E17: 80 | F17: 85 | G17: 90 | H17: 95 | I17: 100 | J17: 105 | K17: 110 | L17: 115 | M17: 120〜 | N17: % | Q17: =IF(OR(P17="",NOT(ISNUMBER(P17))),"—",B17*P17/100)
A18: お困りごと残件数削減（課） | B18: 0.25 | C18: 91〜 | D18: 90 | E18: 82 | F18: 74 | G18: 66 | H18: 58 | I18: 50 | J18: 42 | K18: 34 | L18: 26 | M18: 〜18 | N18: 件 | Q18: =IF(OR(P18="",NOT(ISNUMBER(P18))),"—",B18*P18/100)
A19: 顧客満足度向上（課） | B19: 0.1 | C19: 4.75未満 | D19: — | E19: 4.75 | F19: — | G19: 4.8 | H19: — | I19: 4.85 | J19: +口コミ15 | K19: 20 | L19: 25 | M19: 30 | N19: 点/件 | Q19: =IF(OR(P19="",NOT(ISNUMBER(P19))),"—",B19*P19/100)
A20: アンケート回収率UP（課） | B20: 0.1 | C20: 10未満 | D20: — | E20: 10 | F20: 15 | G20: 20 | H20: 25 | I20: 30 | J20: 35 | K20: 40 | L20: 45 | M20: 50〜 | N20: % | Q20: =IF(OR(P20="",NOT(ISNUMBER(P20))),"—",B20*P20/100)
A21: 原状回復の対応（課） | B21: 0.2 | C21: 7〜 | D21: 6 | E21: 5 | F21: 4 | G21: 3 | H21: 2 | I21: 1 | J21: 60点+3件 | K21: +5件 | L21: +7件 | M21: +9件 | N21: 件 | Q21: =IF(OR(P21="",NOT(ISNUMBER(P21))),"—",B21*P21/100)
A25: Q2 合計点 | Q25: =SUMIF(Q17:Q24,"<>—")
A27: 【Q3】 5月〜7月
A28: 評価項目 | B28: 重み | C28: 基0 | D28: 基10 | E28: 基20 | F28: 基30 | G28: 基40 | H28: 基50 | I28: 基60 | J28: 基70 | K28: 基80 | L28: 基90 | M28: 基100 | N28: 単位 | O28: 結果(入力) | P28: 尺度結果 | Q28: 重み×尺度
A29: 売上目標達成（全社） | B29: 0.35 | C29: 75未満 | D29: 75 | E29: 80 | F29: 85 | G29: 90 | H29: 95 | I29: 100 | J29: 105 | K29: 110 | L29: 115 | M29: 120〜 | N29: % | Q29: =IF(OR(P29="",NOT(ISNUMBER(P29))),"—",B29*P29/100)
A30: お困りごと残件数削減（課） | B30: 0.25 | C30: 91〜 | D30: 90 | E30: 82 | F30: 74 | G30: 66 | H30: 58 | I30: 50 | J30: 42 | K30: 34 | L30: 26 | M30: 〜18 | N30: 件 | Q30: =IF(OR(P30="",NOT(ISNUMBER(P30))),"—",B30*P30/100)
A31: 顧客満足度向上（課） | B31: 0.1 | C31: 4.75未満 | D31: — | E31: 4.75 | F31: — | G31: 4.8 | H31: — | I31: 4.85 | J31: +口コミ15 | K31: 20 | L31: 25 | M31: 30 | N31: 点/件 | Q31: =IF(OR(P31="",NOT(ISNUMBER(P31))),"—",B31*P31/100)
A32: アンケート回収率UP（課） | B32: 0.1 | C32: 10未満 | D32: — | E32: 10 | F32: 15 | G32: 20 | H32: 25 | I32: 30 | J32: 35 | K32: 40 | L32: 45 | M32: 50〜 | N32: % | Q32: =IF(OR(P32="",NOT(ISNUMBER(P32))),"—",B32*P32/100)
A33: 原状回復の対応（課） | B33: 0.2 | C33: 7〜 | D33: 6 | E33: 5 | F33: 4 | G33: 3 | H33: 2 | I33: 1 | J33: 60点+3件 | K33: +5件 | L33: +7件 | M33: +9件 | N33: 件 | Q33: =IF(OR(P33="",NOT(ISNUMBER(P33))),"—",B33*P33/100)
A37: Q3 合計点 | Q37: =SUMIF(Q29:Q36,"<>—")
A39: 【Q4】 8月〜10月
A40: 評価項目 | B40: 重み | C40: 基0 | D40: 基10 | E40: 基20 | F40: 基30 | G40: 基40 | H40: 基50 | I40: 基60 | J40: 基70 | K40: 基80 | L40: 基90 | M40: 基100 | N40: 単位 | O40: 結果(入力) | P40: 尺度結果 | Q40: 重み×尺度
A41: 売上目標達成（全社） | B41: 0.35 | C41: 75未満 | D41: 75 | E41: 80 | F41: 85 | G41: 90 | H41: 95 | I41: 100 | J41: 105 | K41: 110 | L41: 115 | M41: 120〜 | N41: % | Q41: =IF(OR(P41="",NOT(ISNUMBER(P41))),"—",B41*P41/100)
A42: お困りごと残件数削減（課） | B42: 0.25 | C42: 91〜 | D42: 90 | E42: 82 | F42: 74 | G42: 66 | H42: 58 | I42: 50 | J42: 42 | K42: 34 | L42: 26 | M42: 〜18 | N42: 件 | Q42: =IF(OR(P42="",NOT(ISNUMBER(P42))),"—",B42*P42/100)
A43: 顧客満足度向上（課） | B43: 0.1 | C43: 4.75未満 | D43: — | E43: 4.75 | F43: — | G43: 4.8 | H43: — | I43: 4.85 | J43: +口コミ15 | K43: 20 | L43: 25 | M43: 30 | N43: 点/件 | Q43: =IF(OR(P43="",NOT(ISNUMBER(P43))),"—",B43*P43/100)
A44: アンケート回収率UP（課） | B44: 0.1 | C44: 10未満 | D44: — | E44: 10 | F44: 15 | G44: 20 | H44: 25 | I44: 30 | J44: 35 | K44: 40 | L44: 45 | M44: 50〜 | N44: % | Q44: =IF(OR(P44="",NOT(ISNUMBER(P44))),"—",B44*P44/100)
A45: 原状回復の対応（課） | B45: 0.2 | C45: 7〜 | D45: 6 | E45: 5 | F45: 4 | G45: 3 | H45: 2 | I45: 1 | J45: 60点+3件 | K45: +5件 | L45: +7件 | M45: +9件 | N45: 件 | Q45: =IF(OR(P45="",NOT(ISNUMBER(P45))),"—",B45*P45/100)
A49: Q4 合計点 | Q49: =SUMIF(Q41:Q48,"<>—")
A52: 上半期合計（Q1＋Q2） | Q52: =Q13+Q25
A53: 下半期合計（Q3＋Q4） | Q53: =Q37+Q49

Sheet CS新人①
A1: 【個人評価シート】 カスタマー 新人 CS新人①
A3: 【Q1】 11月〜1月
A4: 評価項目 | B4: 重み | C4: 基0 | D4: 基10 | E4: 基20 | F4: 基30 | G4: 基40 | H4: 基50 | I4: 基60 | J4: 基70 | K4: 基80 | L4: 基90 | M4: 基100 | N4: 単位 | O4: 結果(入力) | P4: 尺度結果 | Q4: 重み×尺度
A5: 目標① | B5: 加点 | Q5: —
A6: 目標② | B6: 加点 | Q6: —
A7: 目標③ | B7: 加点 | Q7: —
A8: 【加点】加点項目 | B8: 加点 | Q8: —
A13: Q1 合計点 | Q13: =SUMIF(Q5:Q12,"<>—")
A15: 【Q2】 2月〜4月
A16: 評価項目 | B16: 重み | C16: 基0 | D16: 基10 | E16: 基20 | F16: 基30 | G16: 基40 | H16: 基50 | I16: 基60 | J16: 基70 | K16: 基80 | L16: 基90 | M16: 基100 | N16: 単位 | O16: 結果(入力) | P16: 尺度結果 | Q16: 重み×尺度
A17: 目標① | B17: 加点 | Q17: —
A18: 目標② | B18: 加点 | Q18: —
A19: 目標③ | B19: 加点 | Q19: —
A20: 【加点】加点項目 | B20: 加点 | Q20: —
A25: Q2 合計点 | Q25: =SUMIF(Q17:Q24,"<>—")
A27: 【Q3】 5月〜7月
A28: 評価項目 | B28: 重み | C28: 基0 | D28: 基10 | E28: 基20 | F28: 基30 | G28: 基40 | H28: 基50 | I28: 基60 | J28: 基70 | K28: 基80 | L28: 基90 | M28: 基100 | N28: 単位 | O28: 結果(入力) | P28: 尺度結果 | Q28: 重み×尺度
A29: 目標① | B29: 加点 | Q29: —
A30: 目標② | B30: 加点 | Q30: —
A31: 目標③ | B31: 加点 | Q31: —
A32: 【加点】加点項目 | B32: 加点 | Q32: —
A37: Q3 合計点 | Q37: =SUMIF(Q29:Q36,"<>—")
A39: 【Q4】 8月〜10月
A40: 評価項目 | B40: 重み | C40: 基0 | D40: 基10 | E40: 基20 | F40: 基30 | G40: 基40 | H40: 基50 | I40: 基60 | J40: 基70 | K40: 基80 | L40: 基90 | M40: 基100 | N40: 単位 | O40: 結果(入力) | P40: 尺度結果 | Q40: 重み×尺度
A41: 目標① | B41: 加点 | Q41: —
A42: 目標② | B42: 加点 | Q42: —
A43: 目標③ | B43: 加点 | Q43: —
A44: 【加点】加点項目 | B44: 加点 | Q44: —
A49: Q4 合計点 | Q49: =SUMIF(Q41:Q48,"<>—")
A52: 上半期合計（Q1＋Q2） | Q52: =Q13+Q25
A53: 下半期合計（Q3＋Q4） | Q53: =Q37+Q49

Sheet CS新人②
A1: 【個人評価シート】 カスタマー 新人 CS新人②
A3: 【Q1】 11月〜1月
A4: 評価項目 | B4: 重み | C4: 基0 | D4: 基10 | E4: 基20 | F4: 基30 | G4: 基40 | H4: 基50 | I4: 基60 | J4: 基70 | K4: 基80 | L4: 基90 | M4: 基100 | N4: 単位 | O4: 結果(入力) | P4: 尺度結果 | Q4: 重み×尺度
A5: 目標① | B5: 加点 | Q5: —
A6: 目標② | B6: 加点 | Q6: —
A7: 目標③ | B7: 加点 | Q7: —
A8: 【加点】加点項目 | B8: 加点 | Q8: —
A13: Q1 合計点 | Q13: =SUMIF(Q5:Q12,"<>—")
A15: 【Q2】 2月〜4月
A16: 評価項目 | B16: 重み | C16: 基0 | D16: 基10 | E16: 基20 | F16: 基30 | G16: 基40 | H16: 基50 | I16: 基60 | J16: 基70 | K16: 基80 | L16: 基90 | M16: 基100 | N16: 単位 | O16: 結果(入力) | P16: 尺度結果 | Q16: 重み×尺度
A17: 目標① | B17: 加点 | Q17: —
A18: 目標② | B18: 加点 | Q18: —
A19: 目標③ | B19: 加点 | Q19: —
A20: 【加点】加点項目 | B20: 加点 | Q20: —
A25: Q2 合計点 | Q25: =SUMIF(Q17:Q24,"<>—")
A27: 【Q3】 5月〜7月
A28: 評価項目 | B28: 重み | C28: 基0 | D28: 基10 | E28: 基20 | F28: 基30 | G28: 基40 | H28: 基50 | I28: 基60 | J28: 基70 | K28: 基80 | L28: 基90 | M28: 基100 | N28: 単位 | O28: 結果(入力) | P28: 尺度結果 | Q28: 重み×尺度
A29: 目標① | B29: 加点 | Q29: —
A30: 目標② | B30: 加点 | Q30: —
A31: 目標③ | B31: 加点 | Q31: —
A32: 【加点】加点項目 | B32: 加点 | Q32: —
A37: Q3 合計点 | Q37: =SUMIF(Q29:Q36,"<>—")
A39: 【Q4】 8月〜10月
A40: 評価項目 | B40: 重み | C40: 基0 | D40: 基10 | E40: 基20 | F40: 基30 | G40: 基40 | H40: 基50 | I40: 基60 | J40: 基70 | K40: 基80 | L40: 基90 | M40: 基100 | N40: 単位 | O40: 結果(入力) | P40: 尺度結果 | Q40: 重み×尺度
A41: 目標① | B41: 加点 | Q41: —
A42: 目標② | B42: 加点 | Q42: —
A43: 目標③ | B43: 加点 | Q43: —
A44: 【加点】加点項目 | B44: 加点 | Q44: —
A49: Q4 合計点 | Q49: =SUMIF(Q41:Q48,"<>—")
A52: 上半期合計（Q1＋Q2） | Q52: =Q13+Q25
A53: 下半期合計（Q3＋Q4） | Q53: =Q37+Q49

Sheet 野方
A1: 【個人評価シート】 経営企画 課長 野方
A3: 【Q1】 11月〜1月
A4: 評価項目 | B4: 重み | C4: 基0 | D4: 基10 | E4: 基20 | F4: 基30 | G4: 基40 | H4: 基50 | I4: 基60 | J4: 基70 | K4: 基80 | L4: 基90 | M4: 基100 | N4: 単位 | O4: 結果(入力) | P4: 尺度結果 | Q4: 重み×尺度
A5: 売上目標達成（全社） | B5: 0.4 | C5: 75未満 | D5: 75 | E5: 80 | F5: 85 | G5: 90 | H5: 95 | I5: 100 | J5: 105 | K5: 110 | L5: 115 | M5: 120〜 | N5: % | Q5: =IF(OR(P5="",NOT(ISNUMBER(P5))),"—",B5*P5/100)
A6: 民泊売上目標達成（課） | B6: 0.4 | C6: 75未満 | D6: 75 | E6: 80 | F6: 85 | G6: 90 | H6: 95 | I6: 100 | J6: 105 | K6: 110 | L6: 115 | M6: 120〜 | N6: % | Q6: =IF(OR(P6="",NOT(ISNUMBER(P6))),"—",B6*P6/100)
A7: 民泊新規施策実行（課） | B7: 0.2 | C7: 0 | D7: 10 | E7: 20 | F7: 30 | G7: 40 | H7: 50 | I7: 60 | J7: 70 | K7: 80 | L7: 90 | M7: 100 | N7: 点 | Q7: =IF(OR(P7="",NOT(ISNUMBER(P7))),"—",B7*P7/100)
A13: Q1 合計点 | Q13: =SUMIF(Q5:Q12,"<>—")
A15: 【Q2】 2月〜4月
A16: 評価項目 | B16: 重み | C16: 基0 | D16: 基10 | E16: 基20 | F16: 基30 | G16: 基40 | H16: 基50 | I16: 基60 | J16: 基70 | K16: 基80 | L16: 基90 | M16: 基100 | N16: 単位 | O16: 結果(入力) | P16: 尺度結果 | Q16: 重み×尺度
A17: 売上目標達成（全社） | B17: 0.4 | C17: 75未満 | D17: 75 | E17: 80 | F17: 85 | G17: 90 | H17: 95 | I17: 100 | J17: 105 | K17: 110 | L17: 115 | M17: 120〜 | N17: % | Q17: =IF(OR(P17="",NOT(ISNUMBER(P17))),"—",B17*P17/100)
A18: 民泊売上目標達成（課） | B18: 0.4 | C18: 75未満 | D18: 75 | E18: 80 | F18: 85 | G18: 90 | H18: 95 | I18: 100 | J18: 105 | K18: 110 | L18: 115 | M18: 120〜 | N18: % | Q18: =IF(OR(P18="",NOT(ISNUMBER(P18))),"—",B18*P18/100)
A19: 民泊新規施策実行（課） | B19: 0.2 | C19: 0 | D19: 10 | E19: 20 | F19: 30 | G19: 40 | H19: 50 | I19: 60 | J19: 70 | K19: 80 | L19: 90 | M19: 100 | N19: 点 | Q19: =IF(OR(P19="",NOT(ISNUMBER(P19))),"—",B19*P19/100)
A25: Q2 合計点 | Q25: =SUMIF(Q17:Q24,"<>—")
A27: 【Q3】 5月〜7月
A28: 評価項目 | B28: 重み | C28: 基0 | D28: 基10 | E28: 基20 | F28: 基30 | G28: 基40 | H28: 基50 | I28: 基60 | J28: 基70 | K28: 基80 | L28: 基90 | M28: 基100 | N28: 単位 | O28: 結果(入力) | P28: 尺度結果 | Q28: 重み×尺度
A29: 売上目標達成（全社） | B29: 0.4 | C29: 75未満 | D29: 75 | E29: 80 | F29: 85 | G29: 90 | H29: 95 | I29: 100 | J29: 105 | K29: 110 | L29: 115 | M29: 120〜 | N29: % | Q29: =IF(OR(P29="",NOT(ISNUMBER(P29))),"—",B29*P29/100)
A30: 民泊売上目標達成（課） | B30: 0.4 | C30: 75未満 | D30: 75 | E30: 80 | F30: 85 | G30: 90 | H30: 95 | I30: 100 | J30: 105 | K30: 110 | L30: 115 | M30: 120〜 | N30: % | Q30: =IF(OR(P30="",NOT(ISNUMBER(P30))),"—",B30*P30/100)
A31: 民泊新規施策実行（課） | B31: 0.2 | C31: 0 | D31: 10 | E31: 20 | F31: 30 | G31: 40 | H31: 50 | I31: 60 | J31: 70 | K31: 80 | L31: 90 | M31: 100 | N31: 点 | Q31: =IF(OR(P31="",NOT(ISNUMBER(P31))),"—",B31*P31/100)
A37: Q3 合計点 | Q37: =SUMIF(Q29:Q36,"<>—")
A39: 【Q4】 8月〜10月
A40: 評価項目 | B40: 重み | C40: 基0 | D40: 基10 | E40: 基20 | F40: 基30 | G40: 基40 | H40: 基50 | I40: 基60 | J40: 基70 | K40: 基80 | L40: 基90 | M40: 基100 | N40: 単位 | O40: 結果(入力) | P40: 尺度結果 | Q40: 重み×尺度
A41: 売上目標達成（全社） | B41: 0.4 | C41: 75未満 | D41: 75 | E41: 80 | F41: 85 | G41: 90 | H41: 95 | I41: 100 | J41: 105 | K41: 110 | L41: 115 | M41: 120〜 | N41: % | Q41: =IF(OR(P41="",NOT(ISNUMBER(P41))),"—",B41*P41/100)
A42: 民泊売上目標達成（課） | B42: 0.4 | C42: 75未満 | D42: 75 | E42: 80 | F42: 85 | G42: 90 | H42: 95 | I42: 100 | J42: 105 | K42: 110 | L42: 115 | M42: 120〜 | N42: % | Q42: =IF(OR(P42="",NOT(ISNUMBER(P42))),"—",B42*P42/100)
A43: 民泊新規施策実行（課） | B43: 0.2 | C43: 0 | D43: 10 | E43: 20 | F43: 30 | G43: 40 | H43: 50 | I43: 60 | J43: 70 | K43: 80 | L43: 90 | M43: 100 | N43: 点 | Q43: =IF(OR(P43="",NOT(ISNUMBER(P43))),"—",B43*P43/100)
A49: Q4 合計点 | Q49: =SUMIF(Q41:Q48,"<>—")
A52: 上半期合計（Q1＋Q2） | Q52: =Q13+Q25
A53: 下半期合計（Q3＋Q4） | Q53: =Q37+Q49

Sheet KK新人①
A1: 【個人評価シート】 経営企画 新人 KK新人①
A3: 【Q1】 11月〜1月
A4: 評価項目 | B4: 重み | C4: 基0 | D4: 基10 | E4: 基20 | F4: 基30 | G4: 基40 | H4: 基50 | I4: 基60 | J4: 基70 | K4: 基80 | L4: 基90 | M4: 基100 | N4: 単位 | O4: 結果(入力) | P4: 尺度結果 | Q4: 重み×尺度
A5: 目標① | B5: 加点 | Q5: —
A6: 目標② | B6: 加点 | Q6: —
A7: 目標③ | B7: 加点 | Q7: —
A8: 【加点】加点項目 | B8: 加点 | Q8: —
A13: Q1 合計点 | Q13: =SUMIF(Q5:Q12,"<>—")
A15: 【Q2】 2月〜4月
A16: 評価項目 | B16: 重み | C16: 基0 | D16: 基10 | E16: 基20 | F16: 基30 | G16: 基40 | H16: 基50 | I16: 基60 | J16: 基70 | K16: 基80 | L16: 基90 | M16: 基100 | N16: 単位 | O16: 結果(入力) | P16: 尺度結果 | Q16: 重み×尺度
A17: 目標① | B17: 加点 | Q17: —
A18: 目標② | B18: 加点 | Q18: —
A19: 目標③ | B19: 加点 | Q19: —
A20: 【加点】加点項目 | B20: 加点 | Q20: —
A25: Q2 合計点 | Q25: =SUMIF(Q17:Q24,"<>—")
A27: 【Q3】 5月〜7月
A28: 評価項目 | B28: 重み | C28: 基0 | D28: 基10 | E28: 基20 | F28: 基30 | G28: 基40 | H28: 基50 | I28: 基60 | J28: 基70 | K28: 基80 | L28: 基90 | M28: 基100 | N28: 単位 | O28: 結果(入力) | P28: 尺度結果 | Q28: 重み×尺度
A29: 目標① | B29: 加点 | Q29: —
A30: 目標② | B30: 加点 | Q30: —
A31: 目標③ | B31: 加点 | Q31: —
A32: 【加点】加点項目 | B32: 加点 | Q32: —
A37: Q3 合計点 | Q37: =SUMIF(Q29:Q36,"<>—")
A39: 【Q4】 8月〜10月
A40: 評価項目 | B40: 重み | C40: 基0 | D40: 基10 | E40: 基20 | F40: 基30 | G40: 基40 | H40: 基50 | I40: 基60 | J40: 基70 | K40: 基80 | L40: 基90 | M40: 基100 | N40: 単位 | O40: 結果(入力) | P40: 尺度結果 | Q40: 重み×尺度
A41: 目標① | B41: 加点 | Q41: —
A42: 目標② | B42: 加点 | Q42: —
A43: 目標③ | B43: 加点 | Q43: —
A44: 【加点】加点項目 | B44: 加点 | Q44: —
A49: Q4 合計点 | Q49: =SUMIF(Q41:Q48,"<>—")
A52: 上半期合計（Q1＋Q2） | Q52: =Q13+Q25
A53: 下半期合計（Q3＋Q4） | Q53: =Q37+Q49

Sheet KK新人②
A1: 【個人評価シート】 経営企画 新人 KK新人②
A3: 【Q1】 11月〜1月
A4: 評価項目 | B4: 重み | C4: 基0 | D4: 基10 | E4: 基20 | F4: 基30 | G4: 基40 | H4: 基50 | I4: 基60 | J4: 基70 | K4: 基80 | L4: 基90 | M4: 基100 | N4: 単位 | O4: 結果(入力) | P4: 尺度結果 | Q4: 重み×尺度
A5: 目標① | B5: 加点 | Q5: —
A6: 目標② | B6: 加点 | Q6: —
A7: 目標③ | B7: 加点 | Q7: —
A8: 【加点】加点項目 | B8: 加点 | Q8: —
A13: Q1 合計点 | Q13: =SUMIF(Q5:Q12,"<>—")
A15: 【Q2】 2月〜4月
A16: 評価項目 | B16: 重み | C16: 基0 | D16: 基10 | E16: 基20 | F16: 基30 | G16: 基40 | H16: 基50 | I16: 基60 | J16: 基70 | K16: 基80 | L16: 基90 | M16: 基100 | N16: 単位 | O16: 結果(入力) | P16: 尺度結果 | Q16: 重み×尺度
A17: 目標① | B17: 加点 | Q17: —
A18: 目標② | B18: 加点 | Q18: —
A19: 目標③ | B19: 加点 | Q19: —
A20: 【加点】加点項目 | B20: 加点 | Q20: —
A25: Q2 合計点 | Q25: =SUMIF(Q17:Q24,"<>—")
A27: 【Q3】 5月〜7月
A28: 評価項目 | B28: 重み | C28: 基0 | D28: 基10 | E28: 基20 | F28: 基30 | G28: 基40 | H28: 基50 | I28: 基60 | J28: 基70 | K28: 基80 | L28: 基90 | M28: 基100 | N28: 単位 | O28: 結果(入力) | P28: 尺度結果 | Q28: 重み×尺度
A29: 目標① | B29: 加点 | Q29: —
A30: 目標② | B30: 加点 | Q30: —
A31: 目標③ | B31: 加点 | Q31: —
A32: 【加点】加点項目 | B32: 加点 | Q32: —
A37: Q3 合計点 | Q37: =SUMIF(Q29:Q36,"<>—")
A39: 【Q4】 8月〜10月
A40: 評価項目 | B40: 重み | C40: 基0 | D40: 基10 | E40: 基20 | F40: 基30 | G40: 基40 | H40: 基50 | I40: 基60 | J40: 基70 | K40: 基80 | L40: 基90 | M40: 基100 | N40: 単位 | O40: 結果(入力) | P40: 尺度結果 | Q40: 重み×尺度
A41: 目標① | B41: 加点 | Q41: —
A42: 目標② | B42: 加点 | Q42: —
A43: 目標③ | B43: 加点 | Q43: —
A44: 【加点】加点項目 | B44: 加点 | Q44: —
A49: Q4 合計点 | Q49: =SUMIF(Q41:Q48,"<>—")
A52: 上半期合計（Q1＋Q2） | Q52: =Q13+Q25
A53: 下半期合計（Q3＋Q4） | Q53: =Q37+Q49

Sheet 鹿山
A1: 【個人評価シート】 民泊課 一般 鹿山
A3: 【Q1】 11月〜1月
A4: 評価項目 | B4: 重み | C4: 基0 | D4: 基10 | E4: 基20 | F4: 基30 | G4: 基40 | H4: 基50 | I4: 基60 | J4: 基70 | K4: 基80 | L4: 基90 | M4: 基100 | N4: 単位 | O4: 結果(入力) | P4: 尺度結果 | Q4: 重み×尺度
A5: 目標① | B5: 加点 | Q5: —
A6: 目標② | B6: 加点 | Q6: —
A7: 目標③ | B7: 加点 | Q7: —
A8: 【加点】加点項目 | B8: 加点 | Q8: —
A13: Q1 合計点 | Q13: =SUMIF(Q5:Q12,"<>—")
A15: 【Q2】 2月〜4月
A16: 評価項目 | B16: 重み | C16: 基0 | D16: 基10 | E16: 基20 | F16: 基30 | G16: 基40 | H16: 基50 | I16: 基60 | J16: 基70 | K16: 基80 | L16: 基90 | M16: 基100 | N16: 単位 | O16: 結果(入力) | P16: 尺度結果 | Q16: 重み×尺度
A17: 目標① | B17: 加点 | Q17: —
A18: 目標② | B18: 加点 | Q18: —
A19: 目標③ | B19: 加点 | Q19: —
A20: 【加点】加点項目 | B20: 加点 | Q20: —
A25: Q2 合計点 | Q25: =SUMIF(Q17:Q24,"<>—")
A27: 【Q3】 5月〜7月
A28: 評価項目 | B28: 重み | C28: 基0 | D28: 基10 | E28: 基20 | F28: 基30 | G28: 基40 | H28: 基50 | I28: 基60 | J28: 基70 | K28: 基80 | L28: 基90 | M28: 基100 | N28: 単位 | O28: 結果(入力) | P28: 尺度結果 | Q28: 重み×尺度
A29: 目標① | B29: 加点 | Q29: —
A30: 目標② | B30: 加点 | Q30: —
A31: 目標③ | B31: 加点 | Q31: —
A32: 【加点】加点項目 | B32: 加点 | Q32: —
A37: Q3 合計点 | Q37: =SUMIF(Q29:Q36,"<>—")
A39: 【Q4】 8月〜10月
A40: 評価項目 | B40: 重み | C40: 基0 | D40: 基10 | E40: 基20 | F40: 基30 | G40: 基40 | H40: 基50 | I40: 基60 | J40: 基70 | K40: 基80 | L40: 基90 | M40: 基100 | N40: 単位 | O40: 結果(入力) | P40: 尺度結果 | Q40: 重み×尺度
A41: 目標① | B41: 加点 | Q41: —
A42: 目標② | B42: 加点 | Q42: —
A43: 目標③ | B43: 加点 | Q43: —
A44: 【加点】加点項目 | B44: 加点 | Q44: —
A49: Q4 合計点 | Q49: =SUMIF(Q41:Q48,"<>—")
A52: 上半期合計（Q1＋Q2） | Q52: =Q13+Q25
A53: 下半期合計（Q3＋Q4） | Q53: =Q37+Q49

Sheet 虞
A1: 【個人評価シート】 民泊課 一般 虞
A3: 【Q1】 11月〜1月
A4: 評価項目 | B4: 重み | C4: 基0 | D4: 基10 | E4: 基20 | F4: 基30 | G4: 基40 | H4: 基50 | I4: 基60 | J4: 基70 | K4: 基80 | L4: 基90 | M4: 基100 | N4: 単位 | O4: 結果(入力) | P4: 尺度結果 | Q4: 重み×尺度
A5: 目標① | B5: 加点 | Q5: —
A6: 目標② | B6: 加点 | Q6: —
A7: 目標③ | B7: 加点 | Q7: —
A8: 【加点】加点項目 | B8: 加点 | Q8: —
A13: Q1 合計点 | Q13: =SUMIF(Q5:Q12,"<>—")
A15: 【Q2】 2月〜4月
A16: 評価項目 | B16: 重み | C16: 基0 | D16: 基10 | E16: 基20 | F16: 基30 | G16: 基40 | H16: 基50 | I16: 基60 | J16: 基70 | K16: 基80 | L16: 基90 | M16: 基100 | N16: 単位 | O16: 結果(入力) | P16: 尺度結果 | Q16: 重み×尺度
A17: 目標① | B17: 加点 | Q17: —
A18: 目標② | B18: 加点 | Q18: —
A19: 目標③ | B19: 加点 | Q19: —
A20: 【加点】加点項目 | B20: 加点 | Q20: —
A25: Q2 合計点 | Q25: =SUMIF(Q17:Q24,"<>—")
A27: 【Q3】 5月〜7月
A28: 評価項目 | B28: 重み | C28: 基0 | D28: 基10 | E28: 基20 | F28: 基30 | G28: 基40 | H28: 基50 | I28: 基60 | J28: 基70 | K28: 基80 | L28: 基90 | M28: 基100 | N28: 単位 | O28: 結果(入力) | P28: 尺度結果 | Q28: 重み×尺度
A29: 目標① | B29: 加点 | Q29: —
A30: 目標② | B30: 加点 | Q30: —
A31: 目標③ | B31: 加点 | Q31: —
A32: 【加点】加点項目 | B32: 加点 | Q32: —
A37: Q3 合計点 | Q37: =SUMIF(Q29:Q36,"<>—")
A39: 【Q4】 8月〜10月
A40: 評価項目 | B40: 重み | C40: 基0 | D40: 基10 | E40: 基20 | F40: 基30 | G40: 基40 | H40: 基50 | I40: 基60 | J40: 基70 | K40: 基80 | L40: 基90 | M40: 基100 | N40: 単位 | O40: 結果(入力) | P40: 尺度結果 | Q40: 重み×尺度
A41: 目標① | B41: 加点 | Q41: —
A42: 目標② | B42: 加点 | Q42: —
A43: 目標③ | B43: 加点 | Q43: —
A44: 【加点】加点項目 | B44: 加点 | Q44: —
A49: Q4 合計点 | Q49: =SUMIF(Q41:Q48,"<>—")
A52: 上半期合計（Q1＋Q2） | Q52: =Q13+Q25
A53: 下半期合計（Q3＋Q4） | Q53: =Q37+Q49

Sheet MB新人①
A1: 【個人評価シート】 民泊課 新人 MB新人①
A3: 【Q1】 11月〜1月
A4: 評価項目 | B4: 重み | C4: 基0 | D4: 基10 | E4: 基20 | F4: 基30 | G4: 基40 | H4: 基50 | I4: 基60 | J4: 基70 | K4: 基80 | L4: 基90 | M4: 基100 | N4: 単位 | O4: 結果(入力) | P4: 尺度結果 | Q4: 重み×尺度
A5: 目標① | B5: 加点 | Q5: —
A6: 目標② | B6: 加点 | Q6: —
A7: 目標③ | B7: 加点 | Q7: —
A8: 【加点】加点項目 | B8: 加点 | Q8: —
A13: Q1 合計点 | Q13: =SUMIF(Q5:Q12,"<>—")
A15: 【Q2】 2月〜4月
A16: 評価項目 | B16: 重み | C16: 基0 | D16: 基10 | E16: 基20 | F16: 基30 | G16: 基40 | H16: 基50 | I16: 基60 | J16: 基70 | K16: 基80 | L16: 基90 | M16: 基100 | N16: 単位 | O16: 結果(入力) | P16: 尺度結果 | Q16: 重み×尺度
A17: 目標① | B17: 加点 | Q17: —
A18: 目標② | B18: 加点 | Q18: —
A19: 目標③ | B19: 加点 | Q19: —
A20: 【加点】加点項目 | B20: 加点 | Q20: —
A25: Q2 合計点 | Q25: =SUMIF(Q17:Q24,"<>—")
A27: 【Q3】 5月〜7月
A28: 評価項目 | B28: 重み | C28: 基0 | D28: 基10 | E28: 基20 | F28: 基30 | G28: 基40 | H28: 基50 | I28: 基60 | J28: 基70 | K28: 基80 | L28: 基90 | M28: 基100 | N28: 単位 | O28: 結果(入力) | P28: 尺度結果 | Q28: 重み×尺度
A29: 目標① | B29: 加点 | Q29: —
A30: 目標② | B30: 加点 | Q30: —
A31: 目標③ | B31: 加点 | Q31: —
A32: 【加点】加点項目 | B32: 加点 | Q32: —
A37: Q3 合計点 | Q37: =SUMIF(Q29:Q36,"<>—")
A39: 【Q4】 8月〜10月
A40: 評価項目 | B40: 重み | C40: 基0 | D40: 基10 | E40: 基20 | F40: 基30 | G40: 基40 | H40: 基50 | I40: 基60 | J40: 基70 | K40: 基80 | L40: 基90 | M40: 基100 | N40: 単位 | O40: 結果(入力) | P40: 尺度結果 | Q40: 重み×尺度
A41: 目標① | B41: 加点 | Q41: —
A42: 目標② | B42: 加点 | Q42: —
A43: 目標③ | B43: 加点 | Q43: —
A44: 【加点】加点項目 | B44: 加点 | Q44: —
A49: Q4 合計点 | Q49: =SUMIF(Q41:Q48,"<>—")
A52: 上半期合計（Q1＋Q2） | Q52: =Q13+Q25
A53: 下半期合計（Q3＋Q4） | Q53: =Q37+Q49

Sheet MB新人②
A1: 【個人評価シート】 民泊課 新人 MB新人②
A3: 【Q1】 11月〜1月
A4: 評価項目 | B4: 重み | C4: 基0 | D4: 基10 | E4: 基20 | F4: 基30 | G4: 基40 | H4: 基50 | I4: 基60 | J4: 基70 | K4: 基80 | L4: 基90 | M4: 基100 | N4: 単位 | O4: 結果(入力) | P4: 尺度結果 | Q4: 重み×尺度
A5: 目標① | B5: 加点 | Q5: —
A6: 目標② | B6: 加点 | Q6: —
A7: 目標③ | B7: 加点 | Q7: —
A8: 【加点】加点項目 | B8: 加点 | Q8: —
A13: Q1 合計点 | Q13: =SUMIF(Q5:Q12,"<>—")
A15: 【Q2】 2月〜4月
A16: 評価項目 | B16: 重み | C16: 基0 | D16: 基10 | E16: 基20 | F16: 基30 | G16: 基40 | H16: 基50 | I16: 基60 | J16: 基70 | K16: 基80 | L16: 基90 | M16: 基100 | N16: 単位 | O16: 結果(入力) | P16: 尺度結果 | Q16: 重み×尺度
A17: 目標① | B17: 加点 | Q17: —
A18: 目標② | B18: 加点 | Q18: —
A19: 目標③ | B19: 加点 | Q19: —
A20: 【加点】加点項目 | B20: 加点 | Q20: —
A25: Q2 合計点 | Q25: =SUMIF(Q17:Q24,"<>—")
A27: 【Q3】 5月〜7月
A28: 評価項目 | B28: 重み | C28: 基0 | D28: 基10 | E28: 基20 | F28: 基30 | G28: 基40 | H28: 基50 | I28: 基60 | J28: 基70 | K28: 基80 | L28: 基90 | M28: 基100 | N28: 単位 | O28: 結果(入力) | P28: 尺度結果 | Q28: 重み×尺度
A29: 目標① | B29: 加点 | Q29: —
A30: 目標② | B30: 加点 | Q30: —
A31: 目標③ | B31: 加点 | Q31: —
A32: 【加点】加点項目 | B32: 加点 | Q32: —
A37: Q3 合計点 | Q37: =SUMIF(Q29:Q36,"<>—")
A39: 【Q4】 8月〜10月
A40: 評価項目 | B40: 重み | C40: 基0 | D40: 基10 | E40: 基20 | F40: 基30 | G40: 基40 | H40: 基50 | I40: 基60 | J40: 基70 | K40: 基80 | L40: 基90 | M40: 基100 | N40: 単位 | O40: 結果(入力) | P40: 尺度結果 | Q40: 重み×尺度
A41: 目標① | B41: 加点 | Q41: —
A42: 目標② | B42: 加点 | Q42: —
A43: 目標③ | B43: 加点 | Q43: —
A44: 【加点】加点項目 | B44: 加点 | Q44: —
A49: Q4 合計点 | Q49: =SUMIF(Q41:Q48,"<>—")
A52: 上半期合計（Q1＋Q2） | Q52: =Q13+Q25
A53: 下半期合計（Q3＋Q4） | Q53: =Q37+Q49

Sheet 鬼崎
A1: 【個人評価シート】 総務管理 課長 鬼崎
A3: 【Q1】 11月〜1月
A4: 評価項目 | B4: 重み | C4: 基0 | D4: 基10 | E4: 基20 | F4: 基30 | G4: 基40 | H4: 基50 | I4: 基60 | J4: 基70 | K4: 基80 | L4: 基90 | M4: 基100 | N4: 単位 | O4: 結果(入力) | P4: 尺度結果 | Q4: 重み×尺度
A5: 売上目標達成（全社） | B5: 0.2 | C5: 75未満 | D5: 75 | E5: 80 | F5: 85 | G5: 90 | H5: 95 | I5: 100 | J5: 105 | K5: 110 | L5: 115 | M5: 120〜 | N5: % | Q5: =IF(OR(P5="",NOT(ISNUMBER(P5))),"—",B5*P5/100)
A6: 販管費削減目標 | B6: 0.4 | C6: 未達 | D6: — | E6: — | F6: — | G6: — | H6: — | I6: 月10万 | J6: 月20万 | K6: 月30万 | L6: 月40万 | M6: 月50万〜 | N6: 万円 | Q6: =IF(OR(P6="",NOT(ISNUMBER(P6))),"—",B6*P6/100)
A7: 人事採用目標 | B7: 0.1 | N7: 人 | Q7: =IF(OR(P7="",NOT(ISNUMBER(P7))),"—",B7*P7/100)
A8: その他課題 | B8: 0.3 | N8: — | Q8: =IF(OR(P8="",NOT(ISNUMBER(P8))),"—",B8*P8/100)
A13: Q1 合計点 | Q13: =SUMIF(Q5:Q12,"<>—")
A15: 【Q2】 2月〜4月
A16: 評価項目 | B16: 重み | C16: 基0 | D16: 基10 | E16: 基20 | F16: 基30 | G16: 基40 | H16: 基50 | I16: 基60 | J16: 基70 | K16: 基80 | L16: 基90 | M16: 基100 | N16: 単位 | O16: 結果(入力) | P16: 尺度結果 | Q16: 重み×尺度
A17: 売上目標達成（全社） | B17: 0.2 | C17: 75未満 | D17: 75 | E17: 80 | F17: 85 | G17: 90 | H17: 95 | I17: 100 | J17: 105 | K17: 110 | L17: 115 | M17: 120〜 | N17: % | Q17: =IF(OR(P17="",NOT(ISNUMBER(P17))),"—",B17*P17/100)
A18: 販管費削減目標 | B18: 0.4 | C18: 未達 | D18: — | E18: — | F18: — | G18: — | H18: — | I18: 月10万 | J18: 月20万 | K18: 月30万 | L18: 月40万 | M18: 月50万〜 | N18: 万円 | Q18: =IF(OR(P18="",NOT(ISNUMBER(P18))),"—",B18*P18/100)
A19: 人事採用目標 | B19: 0.1 | N19: 人 | Q19: =IF(OR(P19="",NOT(ISNUMBER(P19))),"—",B19*P19/100)
A20: その他課題 | B20: 0.3 | N20: — | Q20: =IF(OR(P20="",NOT(ISNUMBER(P20))),"—",B20*P20/100)
A25: Q2 合計点 | Q25: =SUMIF(Q17:Q24,"<>—")
A27: 【Q3】 5月〜7月
A28: 評価項目 | B28: 重み | C28: 基0 | D28: 基10 | E28: 基20 | F28: 基30 | G28: 基40 | H28: 基50 | I28: 基60 | J28: 基70 | K28: 基80 | L28: 基90 | M28: 基100 | N28: 単位 | O28: 結果(入力) | P28: 尺度結果 | Q28: 重み×尺度
A29: 売上目標達成（全社） | B29: 0.2 | C29: 75未満 | D29: 75 | E29: 80 | F29: 85 | G29: 90 | H29: 95 | I29: 100 | J29: 105 | K29: 110 | L29: 115 | M29: 120〜 | N29: % | Q29: =IF(OR(P29="",NOT(ISNUMBER(P29))),"—",B29*P29/100)
A30: 販管費削減目標 | B30: 0.4 | C30: 未達 | D30: — | E30: — | F30: — | G30: — | H30: — | I30: 月10万 | J30: 月20万 | K30: 月30万 | L30: 月40万 | M30: 月50万〜 | N30: 万円 | Q30: =IF(OR(P30="",NOT(ISNUMBER(P30))),"—",B30*P30/100)
A31: 人事採用目標 | B31: 0.1 | N31: 人 | Q31: =IF(OR(P31="",NOT(ISNUMBER(P31))),"—",B31*P31/100)
A32: その他課題 | B32: 0.3 | N32: — | Q32: =IF(OR(P32="",NOT(ISNUMBER(P32))),"—",B32*P32/100)
A37: Q3 合計点 | Q37: =SUMIF(Q29:Q36,"<>—")
A39: 【Q4】 8月〜10月
A40: 評価項目 | B40: 重み | C40: 基0 | D40: 基10 | E40: 基20 | F40: 基30 | G40: 基40 | H40: 基50 | I40: 基60 | J40: 基70 | K40: 基80 | L40: 基90 | M40: 基100 | N40: 単位 | O40: 結果(入力) | P40: 尺度結果 | Q40: 重み×尺度
A41: 売上目標達成（全社） | B41: 0.2 | C41: 75未満 | D41: 75 | E41: 80 | F41: 85 | G41: 90 | H41: 95 | I41: 100 | J41: 105 | K41: 110 | L41: 115 | M41: 120〜 | N41: % | Q41: =IF(OR(P41="",NOT(ISNUMBER(P41))),"—",B41*P41/100)
A42: 販管費削減目標 | B42: 0.4 | C42: 未達 | D42: — | E42: — | F42: — | G42: — | H42: — | I42: 月10万 | J42: 月20万 | K42: 月30万 | L42: 月40万 | M42: 月50万〜 | N42: 万円 | Q42: =IF(OR(P42="",NOT(ISNUMBER(P42))),"—",B42*P42/100)
A43: 人事採用目標 | B43: 0.1 | N43: 人 | Q43: =IF(OR(P43="",NOT(ISNUMBER(P43))),"—",B43*P43/100)
A44: その他課題 | B44: 0.3 | N44: — | Q44: =IF(OR(P44="",NOT(ISNUMBER(P44))),"—",B44*P44/100)
A49: Q4 合計点 | Q49: =SUMIF(Q41:Q48,"<>—")
A52: 上半期合計（Q1＋Q2） | Q52: =Q13+Q25
A53: 下半期合計（Q3＋Q4） | Q53: =Q37+Q49

Sheet 池田
A1: 【個人評価シート】 総務管理 主任 池田
A3: 【Q1】 11月〜1月
A4: 評価項目 | B4: 重み | C4: 基0 | D4: 基10 | E4: 基20 | F4: 基30 | G4: 基40 | H4: 基50 | I4: 基60 | J4: 基70 | K4: 基80 | L4: 基90 | M4: 基100 | N4: 単位 | O4: 結果(入力) | P4: 尺度結果 | Q4: 重み×尺度
A5: 売上目標達成（全社） | B5: 0.3 | C5: 75未満 | D5: 75 | E5: 80 | F5: 85 | G5: 90 | H5: 95 | I5: 100 | J5: 105 | K5: 110 | L5: 115 | M5: 120〜 | N5: % | Q5: =IF(OR(P5="",NOT(ISNUMBER(P5))),"—",B5*P5/100)
A6: 業務評価（加点式） | B6: 0.7 | C6: 60点持ち点/上席判断で加減点 | N6: 点 | Q6: =IF(OR(P6="",NOT(ISNUMBER(P6))),"—",B6*P6/100)
A7: 【減点】各種減点 | B7: 加点 | C7: 金銭ミス-3/コンプラ-10 | N7: 点 | Q7: —
A13: Q1 合計点 | Q13: =SUMIF(Q5:Q12,"<>—")
A15: 【Q2】 2月〜4月
A16: 評価項目 | B16: 重み | C16: 基0 | D16: 基10 | E16: 基20 | F16: 基30 | G16: 基40 | H16: 基50 | I16: 基60 | J16: 基70 | K16: 基80 | L16: 基90 | M16: 基100 | N16: 単位 | O16: 結果(入力) | P16: 尺度結果 | Q16: 重み×尺度
A17: 売上目標達成（全社） | B17: 0.3 | C17: 75未満 | D17: 75 | E17: 80 | F17: 85 | G17: 90 | H17: 95 | I17: 100 | J17: 105 | K17: 110 | L17: 115 | M17: 120〜 | N17: % | Q17: =IF(OR(P17="",NOT(ISNUMBER(P17))),"—",B17*P17/100)
A18: 業務評価（加点式） | B18: 0.7 | C18: 60点持ち点/上席判断で加減点 | N18: 点 | Q18: =IF(OR(P18="",NOT(ISNUMBER(P18))),"—",B18*P18/100)
A19: 【減点】各種減点 | B19: 加点 | C19: 金銭ミス-3/コンプラ-10 | N19: 点 | Q19: —
A25: Q2 合計点 | Q25: =SUMIF(Q17:Q24,"<>—")
A27: 【Q3】 5月〜7月
A28: 評価項目 | B28: 重み | C28: 基0 | D28: 基10 | E28: 基20 | F28: 基30 | G28: 基40 | H28: 基50 | I28: 基60 | J28: 基70 | K28: 基80 | L28: 基90 | M28: 基100 | N28: 単位 | O28: 結果(入力) | P28: 尺度結果 | Q28: 重み×尺度
A29: 売上目標達成（全社） | B29: 0.3 | C29: 75未満 | D29: 75 | E29: 80 | F29: 85 | G29: 90 | H29: 95 | I29: 100 | J29: 105 | K29: 110 | L29: 115 | M29: 120〜 | N29: % | Q29: =IF(OR(P29="",NOT(ISNUMBER(P29))),"—",B29*P29/100)
A30: 業務評価（加点式） | B30: 0.7 | C30: 60点持ち点/上席判断で加減点 | N30: 点 | Q30: =IF(OR(P30="",NOT(ISNUMBER(P30))),"—",B30*P30/100)
A31: 【減点】各種減点 | B31: 加点 | C31: 金銭ミス-3/コンプラ-10 | N31: 点 | Q31: —
A37: Q3 合計点 | Q37: =SUMIF(Q29:Q36,"<>—")
A39: 【Q4】 8月〜10月
A40: 評価項目 | B40: 重み | C40: 基0 | D40: 基10 | E40: 基20 | F40: 基30 | G40: 基40 | H40: 基50 | I40: 基60 | J40: 基70 | K40: 基80 | L40: 基90 | M40: 基100 | N40: 単位 | O40: 結果(入力) | P40: 尺度結果 | Q40: 重み×尺度
A41: 売上目標達成（全社） | B41: 0.3 | C41: 75未満 | D41: 75 | E41: 80 | F41: 85 | G41: 90 | H41: 95 | I41: 100 | J41: 105 | K41: 110 | L41: 115 | M41: 120〜 | N41: % | Q41: =IF(OR(P41="",NOT(ISNUMBER(P41))),"—",B41*P41/100)
A42: 業務評価（加点式） | B42: 0.7 | C42: 60点持ち点/上席判断で加減点 | N42: 点 | Q42: =IF(OR(P42="",NOT(ISNUMBER(P42))),"—",B42*P42/100)
A43: 【減点】各種減点 | B43: 加点 | C43: 金銭ミス-3/コンプラ-10 | N43: 点 | Q43: —
A49: Q4 合計点 | Q49: =SUMIF(Q41:Q48,"<>—")
A52: 上半期合計（Q1＋Q2） | Q52: =Q13+Q25
A53: 下半期合計（Q3＋Q4） | Q53: =Q37+Q49

Sheet 田尻
A1: 【個人評価シート】 総務管理 一般 田尻
A3: 【Q1】 11月〜1月
A4: 評価項目 | B4: 重み | C4: 基0 | D4: 基10 | E4: 基20 | F4: 基30 | G4: 基40 | H4: 基50 | I4: 基60 | J4: 基70 | K4: 基80 | L4: 基90 | M4: 基100 | N4: 単位 | O4: 結果(入力) | P4: 尺度結果 | Q4: 重み×尺度
A5: 目標① | B5: 加点 | Q5: —
A6: 目標② | B6: 加点 | Q6: —
A7: 目標③ | B7: 加点 | Q7: —
A8: 【加点】加点項目 | B8: 加点 | Q8: —
A13: Q1 合計点 | Q13: =SUMIF(Q5:Q12,"<>—")
A15: 【Q2】 2月〜4月
A16: 評価項目 | B16: 重み | C16: 基0 | D16: 基10 | E16: 基20 | F16: 基30 | G16: 基40 | H16: 基50 | I16: 基60 | J16: 基70 | K16: 基80 | L16: 基90 | M16: 基100 | N16: 単位 | O16: 結果(入力) | P16: 尺度結果 | Q16: 重み×尺度
A17: 目標① | B17: 加点 | Q17: —
A18: 目標② | B18: 加点 | Q18: —
A19: 目標③ | B19: 加点 | Q19: —
A20: 【加点】加点項目 | B20: 加点 | Q20: —
A25: Q2 合計点 | Q25: =SUMIF(Q17:Q24,"<>—")
A27: 【Q3】 5月〜7月
A28: 評価項目 | B28: 重み | C28: 基0 | D28: 基10 | E28: 基20 | F28: 基30 | G28: 基40 | H28: 基50 | I28: 基60 | J28: 基70 | K28: 基80 | L28: 基90 | M28: 基100 | N28: 単位 | O28: 結果(入力) | P28: 尺度結果 | Q28: 重み×尺度
A29: 目標① | B29: 加点 | Q29: —
A30: 目標② | B30: 加点 | Q30: —
A31: 目標③ | B31: 加点 | Q31: —
A32: 【加点】加点項目 | B32: 加点 | Q32: —
A37: Q3 合計点 | Q37: =SUMIF(Q29:Q36,"<>—")
A39: 【Q4】 8月〜10月
A40: 評価項目 | B40: 重み | C40: 基0 | D40: 基10 | E40: 基20 | F40: 基30 | G40: 基40 | H40: 基50 | I40: 基60 | J40: 基70 | K40: 基80 | L40: 基90 | M40: 基100 | N40: 単位 | O40: 結果(入力) | P40: 尺度結果 | Q40: 重み×尺度
A41: 目標① | B41: 加点 | Q41: —
A42: 目標② | B42: 加点 | Q42: —
A43: 目標③ | B43: 加点 | Q43: —
A44: 【加点】加点項目 | B44: 加点 | Q44: —
A49: Q4 合計点 | Q49: =SUMIF(Q41:Q48,"<>—")
A52: 上半期合計（Q1＋Q2） | Q52: =Q13+Q25
A53: 下半期合計（Q3＋Q4） | Q53: =Q37+Q49

Sheet 宮本
A1: 【個人評価シート】 総務管理 一般 宮本
A3: 【Q1】 11月〜1月
A4: 評価項目 | B4: 重み | C4: 基0 | D4: 基10 | E4: 基20 | F4: 基30 | G4: 基40 | H4: 基50 | I4: 基60 | J4: 基70 | K4: 基80 | L4: 基90 | M4: 基100 | N4: 単位 | O4: 結果(入力) | P4: 尺度結果 | Q4: 重み×尺度
A5: 目標① | B5: 加点 | Q5: —
A6: 目標② | B6: 加点 | Q6: —
A7: 目標③ | B7: 加点 | Q7: —
A8: 【加点】加点項目 | B8: 加点 | Q8: —
A13: Q1 合計点 | Q13: =SUMIF(Q5:Q12,"<>—")
A15: 【Q2】 2月〜4月
A16: 評価項目 | B16: 重み | C16: 基0 | D16: 基10 | E16: 基20 | F16: 基30 | G16: 基40 | H16: 基50 | I16: 基60 | J16: 基70 | K16: 基80 | L16: 基90 | M16: 基100 | N16: 単位 | O16: 結果(入力) | P16: 尺度結果 | Q16: 重み×尺度
A17: 目標① | B17: 加点 | Q17: —
A18: 目標② | B18: 加点 | Q18: —
A19: 目標③ | B19: 加点 | Q19: —
A20: 【加点】加点項目 | B20: 加点 | Q20: —
A25: Q2 合計点 | Q25: =SUMIF(Q17:Q24,"<>—")
A27: 【Q3】 5月〜7月
A28: 評価項目 | B28: 重み | C28: 基0 | D28: 基10 | E28: 基20 | F28: 基30 | G28: 基40 | H28: 基50 | I28: 基60 | J28: 基70 | K28: 基80 | L28: 基90 | M28: 基100 | N28: 単位 | O28: 結果(入力) | P28: 尺度結果 | Q28: 重み×尺度
A29: 目標① | B29: 加点 | Q29: —
A30: 目標② | B30: 加点 | Q30: —
A31: 目標③ | B31: 加点 | Q31: —
A32: 【加点】加点項目 | B32: 加点 | Q32: —
A37: Q3 合計点 | Q37: =SUMIF(Q29:Q36,"<>—")
A39: 【Q4】 8月〜10月
A40: 評価項目 | B40: 重み | C40: 基0 | D40: 基10 | E40: 基20 | F40: 基30 | G40: 基40 | H40: 基50 | I40: 基60 | J40: 基70 | K40: 基80 | L40: 基90 | M40: 基100 | N40: 単位 | O40: 結果(入力) | P40: 尺度結果 | Q40: 重み×尺度
A41: 目標① | B41: 加点 | Q41: —
A42: 目標② | B42: 加点 | Q42: —
A43: 目標③ | B43: 加点 | Q43: —
A44: 【加点】加点項目 | B44: 加点 | Q44: —
A49: Q4 合計点 | Q49: =SUMIF(Q41:Q48,"<>—")
A52: 上半期合計（Q1＋Q2） | Q52: =Q13+Q25
A53: 下半期合計（Q3＋Q4） | Q53: =Q37+Q49

Sheet 松尾
A1: 【個人評価シート】 総務管理 一般 松尾
A3: 【Q1】 11月〜1月
A4: 評価項目 | B4: 重み | C4: 基0 | D4: 基10 | E4: 基20 | F4: 基30 | G4: 基40 | H4: 基50 | I4: 基60 | J4: 基70 | K4: 基80 | L4: 基90 | M4: 基100 | N4: 単位 | O4: 結果(入力) | P4: 尺度結果 | Q4: 重み×尺度
A5: 目標① | B5: 加点 | Q5: —
A6: 目標② | B6: 加点 | Q6: —
A7: 目標③ | B7: 加点 | Q7: —
A8: 【加点】加点項目 | B8: 加点 | Q8: —
A13: Q1 合計点 | Q13: =SUMIF(Q5:Q12,"<>—")
A15: 【Q2】 2月〜4月
A16: 評価項目 | B16: 重み | C16: 基0 | D16: 基10 | E16: 基20 | F16: 基30 | G16: 基40 | H16: 基50 | I16: 基60 | J16: 基70 | K16: 基80 | L16: 基90 | M16: 基100 | N16: 単位 | O16: 結果(入力) | P16: 尺度結果 | Q16: 重み×尺度
A17: 目標① | B17: 加点 | Q17: —
A18: 目標② | B18: 加点 | Q18: —
A19: 目標③ | B19: 加点 | Q19: —
A20: 【加点】加点項目 | B20: 加点 | Q20: —
A25: Q2 合計点 | Q25: =SUMIF(Q17:Q24,"<>—")
A27: 【Q3】 5月〜7月
A28: 評価項目 | B28: 重み | C28: 基0 | D28: 基10 | E28: 基20 | F28: 基30 | G28: 基40 | H28: 基50 | I28: 基60 | J28: 基70 | K28: 基80 | L28: 基90 | M28: 基100 | N28: 単位 | O28: 結果(入力) | P28: 尺度結果 | Q28: 重み×尺度
A29: 目標① | B29: 加点 | Q29: —
A30: 目標② | B30: 加点 | Q30: —
A31: 目標③ | B31: 加点 | Q31: —
A32: 【加点】加点項目 | B32: 加点 | Q32: —
A37: Q3 合計点 | Q37: =SUMIF(Q29:Q36,"<>—")
A39: 【Q4】 8月〜10月
A40: 評価項目 | B40: 重み | C40: 基0 | D40: 基10 | E40: 基20 | F40: 基30 | G40: 基40 | H40: 基50 | I40: 基60 | J40: 基70 | K40: 基80 | L40: 基90 | M40: 基100 | N40: 単位 | O40: 結果(入力) | P40: 尺度結果 | Q40: 重み×尺度
A41: 目標① | B41: 加点 | Q41: —
A42: 目標② | B42: 加点 | Q42: —
A43: 目標③ | B43: 加点 | Q43: —
A44: 【加点】加点項目 | B44: 加点 | Q44: —
A49: Q4 合計点 | Q49: =SUMIF(Q41:Q48,"<>—")
A52: 上半期合計（Q1＋Q2） | Q52: =Q13+Q25
A53: 下半期合計（Q3＋Q4） | Q53: =Q37+Q49

Sheet SZ新人①
A1: 【個人評価シート】 総務管理 新人 SZ新人①
A3: 【Q1】 11月〜1月
A4: 評価項目 | B4: 重み | C4: 基0 | D4: 基10 | E4: 基20 | F4: 基30 | G4: 基40 | H4: 基50 | I4: 基60 | J4: 基70 | K4: 基80 | L4: 基90 | M4: 基100 | N4: 単位 | O4: 結果(入力) | P4: 尺度結果 | Q4: 重み×尺度
A5: 目標① | B5: 加点 | Q5: —
A6: 目標② | B6: 加点 | Q6: —
A7: 目標③ | B7: 加点 | Q7: —
A8: 【加点】加点項目 | B8: 加点 | Q8: —
A13: Q1 合計点 | Q13: =SUMIF(Q5:Q12,"<>—")
A15: 【Q2】 2月〜4月
A16: 評価項目 | B16: 重み | C16: 基0 | D16: 基10 | E16: 基20 | F16: 基30 | G16: 基40 | H16: 基50 | I16: 基60 | J16: 基70 | K16: 基80 | L16: 基90 | M16: 基100 | N16: 単位 | O16: 結果(入力) | P16: 尺度結果 | Q16: 重み×尺度
A17: 目標① | B17: 加点 | Q17: —
A18: 目標② | B18: 加点 | Q18: —
A19: 目標③ | B19: 加点 | Q19: —
A20: 【加点】加点項目 | B20: 加点 | Q20: —
A25: Q2 合計点 | Q25: =SUMIF(Q17:Q24,"<>—")
A27: 【Q3】 5月〜7月
A28: 評価項目 | B28: 重み | C28: 基0 | D28: 基10 | E28: 基20 | F28: 基30 | G28: 基40 | H28: 基50 | I28: 基60 | J28: 基70 | K28: 基80 | L28: 基90 | M28: 基100 | N28: 単位 | O28: 結果(入力) | P28: 尺度結果 | Q28: 重み×尺度
A29: 目標① | B29: 加点 | Q29: —
A30: 目標② | B30: 加点 | Q30: —
A31: 目標③ | B31: 加点 | Q31: —
A32: 【加点】加点項目 | B32: 加点 | Q32: —
A37: Q3 合計点 | Q37: =SUMIF(Q29:Q36,"<>—")
A39: 【Q4】 8月〜10月
A40: 評価項目 | B40: 重み | C40: 基0 | D40: 基10 | E40: 基20 | F40: 基30 | G40: 基40 | H40: 基50 | I40: 基60 | J40: 基70 | K40: 基80 | L40: 基90 | M40: 基100 | N40: 単位 | O40: 結果(入力) | P40: 尺度結果 | Q40: 重み×尺度
A41: 目標① | B41: 加点 | Q41: —
A42: 目標② | B42: 加点 | Q42: —
A43: 目標③ | B43: 加点 | Q43: —
A44: 【加点】加点項目 | B44: 加点 | Q44: —
A49: Q4 合計点 | Q49: =SUMIF(Q41:Q48,"<>—")
A52: 上半期合計（Q1＋Q2） | Q52: =Q13+Q25
A53: 下半期合計（Q3＋Q4） | Q53: =Q37+Q49

Sheet SZ新人②
A1: 【個人評価シート】 総務管理 新人 SZ新人②
A3: 【Q1】 11月〜1月
A4: 評価項目 | B4: 重み | C4: 基0 | D4: 基10 | E4: 基20 | F4: 基30 | G4: 基40 | H4: 基50 | I4: 基60 | J4: 基70 | K4: 基80 | L4: 基90 | M4: 基100 | N4: 単位 | O4: 結果(入力) | P4: 尺度結果 | Q4: 重み×尺度
A5: 目標① | B5: 加点 | Q5: —
A6: 目標② | B6: 加点 | Q6: —
A7: 目標③ | B7: 加点 | Q7: —
A8: 【加点】加点項目 | B8: 加点 | Q8: —
A13: Q1 合計点 | Q13: =SUMIF(Q5:Q12,"<>—")
A15: 【Q2】 2月〜4月
A16: 評価項目 | B16: 重み | C16: 基0 | D16: 基10 | E16: 基20 | F16: 基30 | G16: 基40 | H16: 基50 | I16: 基60 | J16: 基70 | K16: 基80 | L16: 基90 | M16: 基100 | N16: 単位 | O16: 結果(入力) | P16: 尺度結果 | Q16: 重み×尺度
A17: 目標① | B17: 加点 | Q17: —
A18: 目標② | B18: 加点 | Q18: —
A19: 目標③ | B19: 加点 | Q19: —
A20: 【加点】加点項目 | B20: 加点 | Q20: —
A25: Q2 合計点 | Q25: =SUMIF(Q17:Q24,"<>—")
A27: 【Q3】 5月〜7月
A28: 評価項目 | B28: 重み | C28: 基0 | D28: 基10 | E28: 基20 | F28: 基30 | G28: 基40 | H28: 基50 | I28: 基60 | J28: 基70 | K28: 基80 | L28: 基90 | M28: 基100 | N28: 単位 | O28: 結果(入力) | P28: 尺度結果 | Q28: 重み×尺度
A29: 目標① | B29: 加点 | Q29: —
A30: 目標② | B30: 加点 | Q30: —
A31: 目標③ | B31: 加点 | Q31: —
A32: 【加点】加点項目 | B32: 加点 | Q32: —
A37: Q3 合計点 | Q37: =SUMIF(Q29:Q36,"<>—")
A39: 【Q4】 8月〜10月
A40: 評価項目 | B40: 重み | C40: 基0 | D40: 基10 | E40: 基20 | F40: 基30 | G40: 基40 | H40: 基50 | I40: 基60 | J40: 基70 | K40: 基80 | L40: 基90 | M40: 基100 | N40: 単位 | O40: 結果(入力) | P40: 尺度結果 | Q40: 重み×尺度
A41: 目標① | B41: 加点 | Q41: —
A42: 目標② | B42: 加点 | Q42: —
A43: 目標③ | B43: 加点 | Q43: —
A44: 【加点】加点項目 | B44: 加点 | Q44: —
A49: Q4 合計点 | Q49: =SUMIF(Q41:Q48,"<>—")
A52: 上半期合計（Q1＋Q2） | Q52: =Q13+Q25
A53: 下半期合計（Q3＋Q4） | Q53: =Q37+Q49

Sheet 沖田
A1: 【個人評価シート】 管理推進 一般 沖田
A3: 【Q1】 11月〜1月
A4: 評価項目 | B4: 重み | C4: 基0 | D4: 基10 | E4: 基20 | F4: 基30 | G4: 基40 | H4: 基50 | I4: 基60 | J4: 基70 | K4: 基80 | L4: 基90 | M4: 基100 | N4: 単位 | O4: 結果(入力) | P4: 尺度結果 | Q4: 重み×尺度
A5: 売上目標達成（全社） | B5: 0.2 | C5: 75未満 | D5: 75 | E5: 80 | F5: 85 | G5: 90 | H5: 95 | I5: 100 | J5: 105 | K5: 110 | L5: 115 | M5: 120〜 | N5: % | Q5: =IF(OR(P5="",NOT(ISNUMBER(P5))),"—",B5*P5/100)
A6: オーナー交渉PT（個人） | B6: 0.5 | C6: 90未満 | D6: 90 | E6: 120 | F6: 150 | G6: 180 | H6: 210 | I6: 240 | J6: 270 | K6: 300 | L6: 330 | M6: 360〜 | N6: pt | Q6: =IF(OR(P6="",NOT(ISNUMBER(P6))),"—",B6*P6/100)
A7: オーナー提案（個人） | B7: 0.3 | C7: 出来ない | D7: — | E7: — | F7: — | G7: — | H7: — | I7: 担当者可 | J7: 300万 | K7: 600万 | L7: 900万 | M7: 1200万〜 | N7: — | Q7: =IF(OR(P7="",NOT(ISNUMBER(P7))),"—",B7*P7/100)
A8: 【加点】新規管理物件 | B8: 加点 | N8: 棟 | Q8: —
A9: 【加点】売買仲介 | B9: 加点 | N9: 件 | Q9: —
A13: Q1 合計点 | Q13: =SUMIF(Q5:Q12,"<>—")
A15: 【Q2】 2月〜4月
A16: 評価項目 | B16: 重み | C16: 基0 | D16: 基10 | E16: 基20 | F16: 基30 | G16: 基40 | H16: 基50 | I16: 基60 | J16: 基70 | K16: 基80 | L16: 基90 | M16: 基100 | N16: 単位 | O16: 結果(入力) | P16: 尺度結果 | Q16: 重み×尺度
A17: 売上目標達成（全社） | B17: 0.2 | C17: 75未満 | D17: 75 | E17: 80 | F17: 85 | G17: 90 | H17: 95 | I17: 100 | J17: 105 | K17: 110 | L17: 115 | M17: 120〜 | N17: % | Q17: =IF(OR(P17="",NOT(ISNUMBER(P17))),"—",B17*P17/100)
A18: オーナー交渉PT（個人） | B18: 0.5 | C18: 90未満 | D18: 90 | E18: 120 | F18: 150 | G18: 180 | H18: 210 | I18: 240 | J18: 270 | K18: 300 | L18: 330 | M18: 360〜 | N18: pt | Q18: =IF(OR(P18="",NOT(ISNUMBER(P18))),"—",B18*P18/100)
A19: オーナー提案（個人） | B19: 0.3 | C19: 出来ない | D19: — | E19: — | F19: — | G19: — | H19: — | I19: 担当者可 | J19: 300万 | K19: 600万 | L19: 900万 | M19: 1200万〜 | N19: — | Q19: =IF(OR(P19="",NOT(ISNUMBER(P19))),"—",B19*P19/100)
A20: 【加点】新規管理物件 | B20: 加点 | N20: 棟 | Q20: —
A21: 【加点】売買仲介 | B21: 加点 | N21: 件 | Q21: —
A25: Q2 合計点 | Q25: =SUMIF(Q17:Q24,"<>—")
A27: 【Q3】 5月〜7月
A28: 評価項目 | B28: 重み | C28: 基0 | D28: 基10 | E28: 基20 | F28: 基30 | G28: 基40 | H28: 基50 | I28: 基60 | J28: 基70 | K28: 基80 | L28: 基90 | M28: 基100 | N28: 単位 | O28: 結果(入力) | P28: 尺度結果 | Q28: 重み×尺度
A29: 売上目標達成（全社） | B29: 0.2 | C29: 75未満 | D29: 75 | E29: 80 | F29: 85 | G29: 90 | H29: 95 | I29: 100 | J29: 105 | K29: 110 | L29: 115 | M29: 120〜 | N29: % | Q29: =IF(OR(P29="",NOT(ISNUMBER(P29))),"—",B29*P29/100)
A30: オーナー交渉PT（個人） | B30: 0.5 | C30: 90未満 | D30: 90 | E30: 120 | F30: 150 | G30: 180 | H30: 210 | I30: 240 | J30: 270 | K30: 300 | L30: 330 | M30: 360〜 | N30: pt | Q30: =IF(OR(P30="",NOT(ISNUMBER(P30))),"—",B30*P30/100)
A31: オーナー提案（個人） | B31: 0.3 | C31: 出来ない | D31: — | E31: — | F31: — | G31: — | H31: — | I31: 担当者可 | J31: 300万 | K31: 600万 | L31: 900万 | M31: 1200万〜 | N31: — | Q31: =IF(OR(P31="",NOT(ISNUMBER(P31))),"—",B31*P31/100)
A32: 【加点】新規管理物件 | B32: 加点 | N32: 棟 | Q32: —
A33: 【加点】売買仲介 | B33: 加点 | N33: 件 | Q33: —
A37: Q3 合計点 | Q37: =SUMIF(Q29:Q36,"<>—")
A39: 【Q4】 8月〜10月
A40: 評価項目 | B40: 重み | C40: 基0 | D40: 基10 | E40: 基20 | F40: 基30 | G40: 基40 | H40: 基50 | I40: 基60 | J40: 基70 | K40: 基80 | L40: 基90 | M40: 基100 | N40: 単位 | O40: 結果(入力) | P40: 尺度結果 | Q40: 重み×尺度
A41: 売上目標達成（全社） | B41: 0.2 | C41: 75未満 | D41: 75 | E41: 80 | F41: 85 | G41: 90 | H41: 95 | I41: 100 | J41: 105 | K41: 110 | L41: 115 | M41: 120〜 | N41: % | Q41: =IF(OR(P41="",NOT(ISNUMBER(P41))),"—",B41*P41/100)
A42: オーナー交渉PT（個人） | B42: 0.5 | C42: 90未満 | D42: 90 | E42: 120 | F42: 150 | G42: 180 | H42: 210 | I42: 240 | J42: 270 | K42: 300 | L42: 330 | M42: 360〜 | N42: pt | Q42: =IF(OR(P42="",NOT(ISNUMBER(P42))),"—",B42*P42/100)
A43: オーナー提案（個人） | B43: 0.3 | C43: 出来ない | D43: — | E43: — | F43: — | G43: — | H43: — | I43: 担当者可 | J43: 300万 | K43: 600万 | L43: 900万 | M43: 1200万〜 | N43: — | Q43: =IF(OR(P43="",NOT(ISNUMBER(P43))),"—",B43*P43/100)
A44: 【加点】新規管理物件 | B44: 加点 | N44: 棟 | Q44: —
A45: 【加点】売買仲介 | B45: 加点 | N45: 件 | Q45: —
A49: Q4 合計点 | Q49: =SUMIF(Q41:Q48,"<>—")
A52: 上半期合計（Q1＋Q2） | Q52: =Q13+Q25
A53: 下半期合計（Q3＋Q4） | Q53: =Q37+Q49

Sheet KS新人①
A1: 【個人評価シート】 管理推進 新人 KS新人①
A3: 【Q1】 11月〜1月
A4: 評価項目 | B4: 重み | C4: 基0 | D4: 基10 | E4: 基20 | F4: 基30 | G4: 基40 | H4: 基50 | I4: 基60 | J4: 基70 | K4: 基80 | L4: 基90 | M4: 基100 | N4: 単位 | O4: 結果(入力) | P4: 尺度結果 | Q4: 重み×尺度
A5: 目標① | B5: 加点 | Q5: —
A6: 目標② | B6: 加点 | Q6: —
A7: 目標③ | B7: 加点 | Q7: —
A8: 【加点】加点項目 | B8: 加点 | Q8: —
A13: Q1 合計点 | Q13: =SUMIF(Q5:Q12,"<>—")
A15: 【Q2】 2月〜4月
A16: 評価項目 | B16: 重み | C16: 基0 | D16: 基10 | E16: 基20 | F16: 基30 | G16: 基40 | H16: 基50 | I16: 基60 | J16: 基70 | K16: 基80 | L16: 基90 | M16: 基100 | N16: 単位 | O16: 結果(入力) | P16: 尺度結果 | Q16: 重み×尺度
A17: 目標① | B17: 加点 | Q17: —
A18: 目標② | B18: 加点 | Q18: —
A19: 目標③ | B19: 加点 | Q19: —
A20: 【加点】加点項目 | B20: 加点 | Q20: —
A25: Q2 合計点 | Q25: =SUMIF(Q17:Q24,"<>—")
A27: 【Q3】 5月〜7月
A28: 評価項目 | B28: 重み | C28: 基0 | D28: 基10 | E28: 基20 | F28: 基30 | G28: 基40 | H28: 基50 | I28: 基60 | J28: 基70 | K28: 基80 | L28: 基90 | M28: 基100 | N28: 単位 | O28: 結果(入力) | P28: 尺度結果 | Q28: 重み×尺度
A29: 目標① | B29: 加点 | Q29: —
A30: 目標② | B30: 加点 | Q30: —
A31: 目標③ | B31: 加点 | Q31: —
A32: 【加点】加点項目 | B32: 加点 | Q32: —
A37: Q3 合計点 | Q37: =SUMIF(Q29:Q36,"<>—")
A39: 【Q4】 8月〜10月
A40: 評価項目 | B40: 重み | C40: 基0 | D40: 基10 | E40: 基20 | F40: 基30 | G40: 基40 | H40: 基50 | I40: 基60 | J40: 基70 | K40: 基80 | L40: 基90 | M40: 基100 | N40: 単位 | O40: 結果(入力) | P40: 尺度結果 | Q40: 重み×尺度
A41: 目標① | B41: 加点 | Q41: —
A42: 目標② | B42: 加点 | Q42: —
A43: 目標③ | B43: 加点 | Q43: —
A44: 【加点】加点項目 | B44: 加点 | Q44: —
A49: Q4 合計点 | Q49: =SUMIF(Q41:Q48,"<>—")
A52: 上半期合計（Q1＋Q2） | Q52: =Q13+Q25
A53: 下半期合計（Q3＋Q4） | Q53: =Q37+Q49

Sheet KS新人②
A1: 【個人評価シート】 管理推進 新人 KS新人②
A3: 【Q1】 11月〜1月
A4: 評価項目 | B4: 重み | C4: 基0 | D4: 基10 | E4: 基20 | F4: 基30 | G4: 基40 | H4: 基50 | I4: 基60 | J4: 基70 | K4: 基80 | L4: 基90 | M4: 基100 | N4: 単位 | O4: 結果(入力) | P4: 尺度結果 | Q4: 重み×尺度
A5: 目標① | B5: 加点 | Q5: —
A6: 目標② | B6: 加点 | Q6: —
A7: 目標③ | B7: 加点 | Q7: —
A8: 【加点】加点項目 | B8: 加点 | Q8: —
A13: Q1 合計点 | Q13: =SUMIF(Q5:Q12,"<>—")
A15: 【Q2】 2月〜4月
A16: 評価項目 | B16: 重み | C16: 基0 | D16: 基10 | E16: 基20 | F16: 基30 | G16: 基40 | H16: 基50 | I16: 基60 | J16: 基70 | K16: 基80 | L16: 基90 | M16: 基100 | N16: 単位 | O16: 結果(入力) | P16: 尺度結果 | Q16: 重み×尺度
A17: 目標① | B17: 加点 | Q17: —
A18: 目標② | B18: 加点 | Q18: —
A19: 目標③ | B19: 加点 | Q19: —
A20: 【加点】加点項目 | B20: 加点 | Q20: —
A25: Q2 合計点 | Q25: =SUMIF(Q17:Q24,"<>—")
A27: 【Q3】 5月〜7月
A28: 評価項目 | B28: 重み | C28: 基0 | D28: 基10 | E28: 基20 | F28: 基30 | G28: 基40 | H28: 基50 | I28: 基60 | J28: 基70 | K28: 基80 | L28: 基90 | M28: 基100 | N28: 単位 | O28: 結果(入力) | P28: 尺度結果 | Q28: 重み×尺度
A29: 目標① | B29: 加点 | Q29: —
A30: 目標② | B30: 加点 | Q30: —
A31: 目標③ | B31: 加点 | Q31: —
A32: 【加点】加点項目 | B32: 加点 | Q32: —
A37: Q3 合計点 | Q37: =SUMIF(Q29:Q36,"<>—")
A39: 【Q4】 8月〜10月
A40: 評価項目 | B40: 重み | C40: 基0 | D40: 基10 | E40: 基20 | F40: 基30 | G40: 基40 | H40: 基50 | I40: 基60 | J40: 基70 | K40: 基80 | L40: 基90 | M40: 基100 | N40: 単位 | O40: 結果(入力) | P40: 尺度結果 | Q40: 重み×尺度
A41: 目標① | B41: 加点 | Q41: —
A42: 目標② | B42: 加点 | Q42: —
A43: 目標③ | B43: 加点 | Q43: —
A44: 【加点】加点項目 | B44: 加点 | Q44: —
A49: Q4 合計点 | Q49: =SUMIF(Q41:Q48,"<>—")
A52: 上半期合計（Q1＋Q2） | Q52: =Q13+Q25
A53: 下半期合計（Q3＋Q4） | Q53: =Q37+Q49

Sheet Q1分析
A1: 【分析表】Q1分析（11月〜1月）
A2: 氏名 | B2: 部署 | C2: 役職 | D2: Q1 11月〜1月 | E2: 順位
A3: 細田 | B3: リーシング | C3: 課長代理 | D3: ='細田'!Q13 | E3: — | F3: =IFERROR(RANK(E3,E3:E29,0),"")
A4: 本多 | B4: リーシング | C4: 一般 | D4: ='本多'!Q13 | E4: — | F4: =IFERROR(RANK(E4,E3:E29,0),"")
A5: 西村 | B5: リーシング | C5: 一般 | D5: ='西村'!Q13 | E5: — | F5: =IFERROR(RANK(E5,E3:E29,0),"")
A6: 村田 | B6: リーシング | C6: 一般 | D6: ='村田'!Q13 | E6: — | F6: =IFERROR(RANK(E6,E3:E29,0),"")
A7: 吉田 | B7: リーシング | C7: 一般 | D7: ='吉田'!Q13 | E7: — | F7: =IFERROR(RANK(E7,E3:E29,0),"")
A8: LS新人① | B8: リーシング | C8: 新人 | D8: ='LS新人①'!Q13 | E8: — | F8: =IFERROR(RANK(E8,E3:E29,0),"")
A9: LS新人② | B9: リーシング | C9: 新人 | D9: ='LS新人②'!Q13 | E9: — | F9: =IFERROR(RANK(E9,E3:E29,0),"")
A10: 奥村 | B10: カスタマー | C10: 課長代理 | D10: ='奥村'!Q13 | E10: — | F10: =IFERROR(RANK(E10,E3:E29,0),"")
A11: CS新人① | B11: カスタマー | C11: 新人 | D11: ='CS新人①'!Q13 | E11: — | F11: =IFERROR(RANK(E11,E3:E29,0),"")
A12: CS新人② | B12: カスタマー | C12: 新人 | D12: ='CS新人②'!Q13 | E12: — | F12: =IFERROR(RANK(E12,E3:E29,0),"")
A13: 野方 | B13: 経営企画 | C13: 課長 | D13: ='野方'!Q13 | E13: — | F13: =IFERROR(RANK(E13,E3:E29,0),"")
A14: KK新人① | B14: 経営企画 | C14: 新人 | D14: ='KK新人①'!Q13 | E14: — | F14: =IFERROR(RANK(E14,E3:E29,0),"")
A15: KK新人② | B15: 経営企画 | C15: 新人 | D15: ='KK新人②'!Q13 | E15: — | F15: =IFERROR(RANK(E15,E3:E29,0),"")
A16: 鹿山 | B16: 民泊課 | C16: 一般 | D16: ='鹿山'!Q13 | E16: — | F16: =IFERROR(RANK(E16,E3:E29,0),"")
A17: 虞 | B17: 民泊課 | C17: 一般 | D17: ='虞'!Q13 | E17: — | F17: =IFERROR(RANK(E17,E3:E29,0),"")
A18: MB新人① | B18: 民泊課 | C18: 新人 | D18: ='MB新人①'!Q13 | E18: — | F18: =IFERROR(RANK(E18,E3:E29,0),"")
A19: MB新人② | B19: 民泊課 | C19: 新人 | D19: ='MB新人②'!Q13 | E19: — | F19: =IFERROR(RANK(E19,E3:E29,0),"")
A20: 鬼崎 | B20: 総務管理 | C20: 課長 | D20: ='鬼崎'!Q13 | E20: — | F20: =IFERROR(RANK(E20,E3:E29,0),"")
A21: 池田 | B21: 総務管理 | C21: 主任 | D21: ='池田'!Q13 | E21: — | F21: =IFERROR(RANK(E21,E3:E29,0),"")
A22: 田尻 | B22: 総務管理 | C22: 一般 | D22: ='田尻'!Q13 | E22: — | F22: =IFERROR(RANK(E22,E3:E29,0),"")
A23: 宮本 | B23: 総務管理 | C23: 一般 | D23: ='宮本'!Q13 | E23: — | F23: =IFERROR(RANK(E23,E3:E29,0),"")
A24: 松尾 | B24: 総務管理 | C24: 一般 | D24: ='松尾'!Q13 | E24: — | F24: =IFERROR(RANK(E24,E3:E29,0),"")
A25: SZ新人① | B25: 総務管理 | C25: 新人 | D25: ='SZ新人①'!Q13 | E25: — | F25: =IFERROR(RANK(E25,E3:E29,0),"")
A26: SZ新人② | B26: 総務管理 | C26: 新人 | D26: ='SZ新人②'!Q13 | E26: — | F26: =IFERROR(RANK(E26,E3:E29,0),"")
A27: 沖田 | B27: 管理推進 | C27: 一般 | D27: ='沖田'!Q13 | E27: — | F27: =IFERROR(RANK(E27,E3:E29,0),"")
A28: KS新人① | B28: 管理推進 | C28: 新人 | D28: ='KS新人①'!Q13 | E28: — | F28: =IFERROR(RANK(E28,E3:E29,0),"")
A29: KS新人② | B29: 管理推進 | C29: 新人 | D29: ='KS新人②'!Q13 | E29: — | F29: =IFERROR(RANK(E29,E3:E29,0),"")

Sheet Q2分析
A1: 【分析表】Q2分析（2月〜4月）
A2: 氏名 | B2: 部署 | C2: 役職 | D2: Q2 2月〜4月 | E2: 順位
A3: 細田 | B3: リーシング | C3: 課長代理 | D3: ='細田'!Q25 | E3: — | F3: =IFERROR(RANK(E3,E3:E29,0),"")
A4: 本多 | B4: リーシング | C4: 一般 | D4: ='本多'!Q25 | E4: — | F4: =IFERROR(RANK(E4,E3:E29,0),"")
A5: 西村 | B5: リーシング | C5: 一般 | D5: ='西村'!Q25 | E5: — | F5: =IFERROR(RANK(E5,E3:E29,0),"")
A6: 村田 | B6: リーシング | C6: 一般 | D6: ='村田'!Q25 | E6: — | F6: =IFERROR(RANK(E6,E3:E29,0),"")
A7: 吉田 | B7: リーシング | C7: 一般 | D7: ='吉田'!Q25 | E7: — | F7: =IFERROR(RANK(E7,E3:E29,0),"")
A8: LS新人① | B8: リーシング | C8: 新人 | D8: ='LS新人①'!Q25 | E8: — | F8: =IFERROR(RANK(E8,E3:E29,0),"")
A9: LS新人② | B9: リーシング | C9: 新人 | D9: ='LS新人②'!Q25 | E9: — | F9: =IFERROR(RANK(E9,E3:E29,0),"")
A10: 奥村 | B10: カスタマー | C10: 課長代理 | D10: ='奥村'!Q25 | E10: — | F10: =IFERROR(RANK(E10,E3:E29,0),"")
A11: CS新人① | B11: カスタマー | C11: 新人 | D11: ='CS新人①'!Q25 | E11: — | F11: =IFERROR(RANK(E11,E3:E29,0),"")
A12: CS新人② | B12: カスタマー | C12: 新人 | D12: ='CS新人②'!Q25 | E12: — | F12: =IFERROR(RANK(E12,E3:E29,0),"")
A13: 野方 | B13: 経営企画 | C13: 課長 | D13: ='野方'!Q25 | E13: — | F13: =IFERROR(RANK(E13,E3:E29,0),"")
A14: KK新人① | B14: 経営企画 | C14: 新人 | D14: ='KK新人①'!Q25 | E14: — | F14: =IFERROR(RANK(E14,E3:E29,0),"")
A15: KK新人② | B15: 経営企画 | C15: 新人 | D15: ='KK新人②'!Q25 | E15: — | F15: =IFERROR(RANK(E15,E3:E29,0),"")
A16: 鹿山 | B16: 民泊課 | C16: 一般 | D16: ='鹿山'!Q25 | E16: — | F16: =IFERROR(RANK(E16,E3:E29,0),"")
A17: 虞 | B17: 民泊課 | C17: 一般 | D17: ='虞'!Q25 | E17: — | F17: =IFERROR(RANK(E17,E3:E29,0),"")
